Workbook

Sheet READ ME
A1: PANDUAN
A2: Isi yang berwarna | D2: aja (jgn malu menjadi pinky boy)
A4: Untuk yg pake sheer, isi warna | E4: di sheet "Perhitungan Main Part". Yang ga pake sheer, gausah.
A6: Baca comment di cell yg ada comment nya
A8: Jangan mengganti jumlah WL
A10: Skala di Sketsa jangan lupa di sesuaikan sendiri

Sheet Tabel Offset
A1: TABLE ORDINATE OF HALF BREADTH | Z1: Principal Dimensions
A2: NO STATION | B2: HALF BREADTH (m) | W2: NO STATION | Z2: Type | AA2: General Cargo
B3: Baseline | C3: WL | D3: WL | E3: WL | F3: WL | G3: WL | H3: WL | I3: WL | J3: WL | K3: WL | L3: WL | M3: WL | N3: WL | O3: WL | P3: WL | Q3: WL | R3: WL | S3: WL | T3: WL | U3: WL | V3: WL | Z3: Loa | AA3: 100.87 | AB3: m
C4: 0.25 | D4: 0.5 | E4: 0.75 | F4: 1 | G4: 1.5 | H4: 2 | I4: 2.5 | J4: 3 | K4: 3.5 | L4: 4 | M4: 4.5 | N4: 5 | O4: 5.5 | P4: 6 | Q4: 6.25 | R4: 6.5 | S4: =AVERAGE(R4,T4) -> 6.85 | T4: =AVERAGE(R4,V4) -> 7.2 | U4: =AVERAGE(T4,V4) -> 7.55 | V4: 7.9 | Z4: Lpp | AA4: 95.07 | AB4: m
A5: Transom | R5: 0.5505 | S5: 1.3981 | T5: 2.03 | U5: 2.5747 | V5: 3.0576 | W5: =A5 -> Transom | X5: Tr - A | Y5: =(AA11-AA4)/2 -> 1.9 | Z5: B | AA5: 16 | AB5: m
A6: A | P6: 0.5375 | Q6: 1.083 | R6: 1.5935 | S6: 2.21 | T6: 2.7516 | U6: 3.2456 | V6: 3.7108 | W6: A | Z6: H | AA6: 7.9 | AB6: m
A7: AP | O7: 0.6606 | P7: 1.652 | Q7: 2.0552 | R7: 2.442 | S7: 2.9635 | T7: 3.4637 | U7: 3.9378 | V7: 4.381 | W7: =A7 -> AP | X7: A - AP | Y7: =Y5 -> 1.9 | Z7: T | AA7: 6.31 | AB7: m
A8: 0.5 | F8: 0.126 | G8: 0.408 | H8: 0.579 | I8: 0.726 | J8: 0.8416 | K8: 0.9278 | L8: 1.0852 | M8: 1.4456 | N8: 1.9207 | O8: 2.4032 | P8: 2.9306 | Q8: 3.2115 | R8: 3.5166 | S8: 3.9625 | T8: 4.3792 | U8: 4.7765 | V8: 5.1792 | W8: =A8 -> 0.5 | Z8: Vs | AA8: 12 | AB8: knot
A9: 1 | B9: 0 | C9: 0.2612 | D9: 0.5213 | E9: 0.7287 | F9: 0.908 | G9: 1.2141 | H9: 1.4761 | I9: 1.7167 | J9: 1.9563 | K9: 2.2093 | L9: 2.4785 | M9: 2.7705 | N9: 3.1349 | O9: 3.5859 | P9: 4.0891 | Q9: 4.3596 | R9: 4.6355 | S9: 5.0395 | T9: 5.4706 | U9: 5.8748 | V9: 6.207 | W9: =A9 -> 1
A10: 1.5 | B10: 0.018 | C10: 0.6839 | D10: 1.0291 | E10: 1.2899 | F10: 1.5044 | G10: 1.859 | H10: 2.1913 | I10: 2.5159 | J10: 2.8159 | K10: 3.1036 | L10: 3.4388 | M10: 3.8023 | N10: 4.2317 | O10: 4.725 | P10: 5.2425 | Q10: 5.5101 | R10: 5.788 | S10: 8.141 | T10: 6.4225 | U10: 6.654 | V10: 6.8489 | W10: 1.5
A11: 2 | B11: 0.076 | C11: 1.0672 | D11: 1.521 | E11: 1.8553 | F11: 2.1235 | G11: 2.609 | H11: 3.0713 | I11: 3.4531 | J11: 3.7939 | K11: 4.132 | L11: 4.4604 | M11: 4.8564 | N11: 5.2958 | O11: 5.75 | P11: 6.2245 | Q11: 6.444 | R11: 6.6256 | S11: 6.8285 | T11: 6.9941 | U11: 7.1372 | V11: 7.2625 | W11: =A11 -> 2 | Z11: Lwl | AA11: 98.87 | AB11: m
A12: 3 | B12: 0.241 | C12: 2.3513 | D12: 3.0826 | E12: 3.5334 | F12: 3.9111 | G12: 4.5731 | H12: 5.0314 | I12: 5.4565 | J12: 5.8073 | K12: 6.1227 | L12: 6.4538 | M12: 6.7876 | N12: 7.1274 | O12: 7.3618 | P12: 7.5007 | Q12: 7.5528 | R12: 7.5999 | S12: 7.6603 | T12: 7.7147 | U12: 7.7634 | V12: 7.8069 | W12: =A12 -> 3 | Z12: ρ | AA12: 1.025 | AB12: ton/m^3
A13: 4 | B13: 0.53 | C13: 4.538 | D13: 5.2295 | E13: 5.6176 | F13: 5.942 | G13: 6.4107 | H13: 6.8182 | I13: 7.1653 | J13: 7.4387 | K13: 7.645 | L13: 7.7888 | M13: 7.8757 | N13: 7.9269 | O13: 7.9618 | P13: 7.9876 | Q13: 7.9984 | R13: 8.0084 | S13: 8.0215 | T13: 8.0335 | U13: 8.0445 | V13: 8.0545 | W13: =A13 -> 4
A14: 5 | B14: 1.075 | C14: 6.5491 | D14: 6.9298 | E14: 7.2003 | F14: 7.4073 | G14: 7.6882 | H14: 7.9081 | I14: 8.0208 | J14: 8.0664 | K14: 8.0914 | L14: 8.1066 | M14: 8.1149 | N14: 8.1196 | O14: 8.1232 | P14: 8.1263 | Q14: 8.1276 | R14: 8.1289 | S14: 8.1305 | T14: 8.1319 | U14: 8.1332 | V14: 8.1343 | W14: =A14 -> 5
A15: 6 | B15: 2.979 | C15: 7.4683 | D15: 7.765 | E15: 7.9116 | F15: 8.0008 | G15: 8.0995 | H15: 8.1225 | I15: 8.1308 | J15: 8.1437 | K15: 8.1406 | L15: 8.1419 | M15: 8.1426 | N15: 8.1431 | O15: 8.1434 | P15: 8.1438 | Q15: 8.144 | R15: 8.144 | S15: 8.144 | T15: 8.144 | U15: 8.144 | V15: 8.144 | W15: =A15 -> 6
A16: 7 | B16: 6.5716 | C16: 7.8266 | D16: 8.0092 | E16: 8.0868 | F16: 8.1173 | G16: 8.1322 | H16: 8.1383 | I16: 8.1421 | J16: 8.144 | K16: 8.144 | L16: 8.144 | M16: 8.144 | N16: 8.144 | O16: 8.144 | P16: 8.144 | Q16: 8.144 | R16: 8.144 | S16: 8.144 | T16: 8.144 | U16: 8.144 | V16: 8.144 | W16: =A16 -> 7
A17: 8 | B17: 6.5716 | C17: 8.144 | D17: 8.144 | E17: 8.144 | F17: 8.144 | G17: 8.144 | H17: 8.144 | I17: 8.144 | J17: 8.144 | K17: 8.144 | L17: 8.144 | M17: 8.144 | N17: 8.144 | O17: 8.144 | P17: 8.144 | Q17: 8.144 | R17: 8.144 | S17: 8.144 | T17: 8.144 | U17: 8.144 | V17: 8.144 | W17: =A17 -> 8
A18: 9 | B18: 6.5716 | C18: 8.144 | D18: 8.144 | E18: 8.144 | F18: 8.144 | G18: 8.144 | H18: 8.144 | I18: 8.144 | J18: 8.144 | K18: 8.144 | L18: 8.144 | M18: 8.144 | N18: 8.144 | O18: 8.144 | P18: 8.144 | Q18: 8.144 | R18: 8.144 | S18: 8.144 | T18: 8.144 | U18: 8.144 | V18: 8.144 | W18: =A18 -> 9
A19: 10 | B19: 6.5716 | C19: 8.144 | D19: 8.144 | E19: 8.144 | F19: 8.144 | G19: 8.144 | H19: 8.144 | I19: 8.144 | J19: 8.144 | K19: 8.144 | L19: 8.144 | M19: 8.144 | N19: 8.144 | O19: 8.144 | P19: 8.144 | Q19: 8.144 | R19: 8.144 | S19: 8.144 | T19: 8.144 | U19: 8.144 | V19: 8.144 | W19: =A19 -> 10
A20: 11 | B20: 6.5716 | C20: 8.144 | D20: 8.144 | E20: 8.144 | F20: 8.144 | G20: 8.144 | H20: 8.144 | I20: 8.144 | J20: 8.144 | K20: 8.144 | L20: 8.144 | M20: 8.144 | N20: 8.144 | O20: 8.144 | P20: 8.144 | Q20: 8.144 | R20: 8.144 | S20: 8.144 | T20: 8.144 | U20: 8.144 | V20: 8.144 | W20: =A20 -> 11
A21: 12 | B21: 6.5716 | C21: 8.144 | D21: 8.144 | E21: 8.144 | F21: 8.144 | G21: 8.144 | H21: 8.144 | I21: 8.144 | J21: 8.144 | K21: 8.144 | L21: 8.144 | M21: 8.144 | N21: 8.144 | O21: 8.144 | P21: 8.144 | Q21: 8.144 | R21: 8.144 | S21: 8.144 | T21: 8.144 | U21: 8.144 | V21: 8.144 | W21: =A21 -> 12
A22: 13 | B22: 6.847 | C22: 8.144 | D22: 8.144 | E22: 8.144 | F22: 8.144 | G22: 8.144 | H22: 8.144 | I22: 8.144 | J22: 8.144 | K22: 8.144 | L22: 8.144 | M22: 8.144 | N22: 8.144 | O22: 8.144 | P22: 8.144 | Q22: 8.144 | R22: 8.144 | S22: 8.144 | T22: 8.144 | U22: 8.144 | V22: 8.144 | W22: =A22 -> 13
A23: 14 | B23: 6.697 | C23: 7.821 | D23: 8.0076 | E23: 8.084 | F23: 8.1144 | G23: 8.1304 | H23: 8.1373 | I23: 8.1412 | J23: 8.1435 | K23: 8.144 | L23: 8.144 | M23: 8.144 | N23: 8.144 | O23: 8.144 | P23: 8.144 | Q23: 8.144 | R23: 8.144 | S23: 8.144 | T23: 8.144 | U23: 8.144 | V23: 8.144 | W23: =A23 -> 14
A24: 15 | B24: 6.305 | C24: 7.198 | D24: 7.5349 | E24: 7.7169 | F24: 7.8233 | G24: 7.9036 | H24: 7.9396 | I24: 7.9703 | J24: 7.9987 | K24: 8.0253 | L24: 8.0499 | M24: 8.0716 | N24: 8.0895 | O24: 8.1029 | P24: 8.1125 | Q24: 8.1164 | R24: 8.1198 | S24: 8.1239 | T24: 8.1274 | U24: 8.1303 | V24: 8.1327 | W24: =A24 -> 15
... A30: 19.5 | B30: 0 | C30: 0 | D30: 0.411 | E30: 0.7389 | F30: 0.9469 | G30: 1.199 | H30: 1.4209 | I30: 1.629 | J30: 1.814 | K30: 1.9725 | L30: 2.1211 | M30: 2.265 | N30: 2.4046 | O30: 2.5406 | P30: 2.6729 | Q30: 2.7376 | R30: 2.8013 | S30: 2.8885 | T30: 2.9731 | U30: 3.0549 | V30: 3.31343 | W30: =A30 -> 19.5
A31: FP | R31: 0.1624 | S31: 0.2674 | T31: 0.3696 | U31: 0.4779 | V31: 0.579 | W31: =A31 -> FP
B33: TABLE OF HALF-BREADTH
B34: NO. | C34: HALF-BREADTH PLAN (m) | O34: NO.
C35: FLAT OF BOTTOM | D35: WL | E35: WL | F35: WL | G35: WL | H35: WL | I35: WL | J35: WL | K35: WL | L35: MD | M35: PD | N35: FORECASTLE DECK | O35: BULWARK
B36: STATION | D36: 0.5 | E36: 1 | F36: 1.5 | G36: 2 | H36: 3 | I36: 4 | J36: 5 | K36: 6.3
B37: Transom | L37: 4.034 | M37: 5.074 | O37: 5.401
B38: A | K38: 0.871 | L38: 4.697 | M38: 5.47 | O38: 5.713
B39: AP | K39: 1.831 | L39: 5.211 | M39: 5.859 | O39: 6.057
B40: 0.5 | E40: 0.298 | F40: 0.431 | G40: 0.44 | H40: 0.282 | I40: 0.265 | J40: 1.129 | K40: 2.645 | L40: 5.66 | M40: 6.279 | O40: 6.443
B41: 1 | D41: 1.292 | E41: 1.48 | F41: 1.592 | G41: 1.678 | H41: 1.825 | I41: 2.055 | J41: 2.507 | K41: 3.636 | L41: 5.64 | M41: 6.431 | O41: 6.565
B42: 1.5 | C42: 0.27 | D42: 2.598 | E42: 2.78 | F42: 2.896 | G42: 2.993 | H42: 3.138 | I42: 3.323 | J42: 3.644 | K42: 4.419 | L42: 6.015 | M42: 6.559 | O42: 6.662
B43: 2 | C43: 0.426 | D43: 4.063 | E43: 4.193 | F43: 4.273 | G43: 4.329 | H43: 4.436 | I43: 4.582 | J43: 4.835 | K43: 5.417 | L43: 6.352 | M43: 6.697 | O43: 6.767
B44: 3 | C44: 0.289 | D44: 5.76 | E44: 5.862 | F44: 5.909 | G44: 5.946 | H44: 6.013 | I44: 6.101 | J44: 6.255 | K44: 6.575 | L44: 6.812 | M44: 6.922 | O44: 6.956
B45: 4 | C45: 0.667 | D45: 6.545 | E45: 6.617 | F45: 6.658 | G45: 6.688 | H45: 6.735 | I45: 6.793 | J45: 6.88 | K45: 6.974 | L45: 7.017 | O45: 7.054
B46: 5 | C46: 3.166 | D46: 6.708 | E46: 6.776 | F46: 6.815 | G46: 6.843 | H46: 6.887 | I46: 6.936 | J46: 6.989 | K46: 7.038 | L46: 7.07 | O46: 7.089
...

Sheet Sheet1
A1: Baseline | B1: 0,001
A2: WL 0.25 | B2: 0,250
A3: WL 0.50 | B3: 0,500
A4: WL 0.75 | B4: 0,750
A5: WL 1.00 | B5: 1000
A6: WL 1.50 | B6: 1500
A7: WL 2.00 | B7: 2000
A8: WL 2.50 | B8: 2500
A9: WL 3.00 | B9: 3000
A10: WL 3.50 | B10: 3500
A11: WL 4.00 | B11: 4000
A12: WL 4.50 | B12: 4500
A13: WL 5.00 | B13: 5000
A14: WL 5.50 | B14: 5500
A15: WL 6.00 | B15: 6000
A16: WL 6.10 | B16: 6100
... A21: WL 7.80 | B21: 7800

Sheet Perhitungan Main Part
DR1: PERHITUNGAN LUAS DARI H SAMPAI SHEER
B2: ST | C2: X | D2: 0 | E2: m WL | F2: ~ | G2: ='Tabel Offset'!D4 -> 0.5 | H2: m WL | I2: h = | J2: =(G2-D2)/2 -> 0.25 | K2: m | N2: ST | O2: X | P2: ='Tabel Offset'!D4 -> 0.5 | Q2: m WL | R2: ~ | S2: ='Tabel Offset'!F4 -> 1 | T2: m WL | U2: h = | V2: =(S2-P2)/2 -> 0.25 | W2: m | Z2: ST | AA2: X | AB2: ='Tabel Offset'!F4 -> 1 | AC2: m WL | AD2: ~ | AE2: ='Tabel Offset'!H4 -> 2 | AF2: m WL | AG2: h = | AH2: =(AE2-AB2)/2 -> 0.5 | AI2: m | AL2: ST | AM2: X | AN2: ='Tabel Offset'!H4 -> 2 | AO2: m WL | AP2: ~ | AQ2: ='Tabel Offset'!J4 -> 3 | AR2: m WL | AS2: h = | AT2: =(AQ2-AN2)/2 -> 0.5 | AU2: m | AX2: ST | AY2: X | AZ2: ='Tabel Offset'!J4 -> 3 | BA2: m WL | BB2: ~ | BC2: ='Tabel Offset'!L4 -> 4 | BD2: m WL | BE2: h = | BF2: =(BC2-AZ2)/2 -> 0.5 | BG2: m | BJ2: ST | BK2: X | BL2: ='Tabel Offset'!L4 -> 4 | BM2: m WL | BN2: ~ | BO2: ='Tabel Offset'!N4 -> 5 | BP2: m WL | BQ2: h = | BR2: =(BO2-BL2)/2 -> 0.5 | BS2: m | BV2: ST | BW2: X | BX2: ='Tabel Offset'!N4 -> 5 | BY2: m WL | BZ2: ~ | CA2: ='Tabel Offset'!P4 -> 6 | CB2: m WL | CC2: h = | CD2: =(CA2-BX2)/2 -> 0.5 | CE2: m | CH2: ST | CI2: X | CJ2: ='Tabel Offset'!P4 -> 6 | CK2: m WL | CL2: ~ | CM2: ='Tabel Offset'!R4 -> 6.5 | CN2: m WL | CO2: h = | CP2: =(CM2-CJ2)/2 -> 0.25 | CQ2: m | CT2: ST | CU2: X | CV2: ='Tabel Offset'!R4 -> 6.5 | CW2: m WL | CX2: ~ | CY2: ='Tabel Offset'!T4 -> 7.2 | CZ2: m WL | DA2: h = | DB2: =(CY2-CV2)/2 -> 0.35 | DC2: m | DF2: ST | DG2: X | DH2: ='Tabel Offset'!T4 -> 7.2 | DI2: m WL | DJ2: ~ | DK2: ='Tabel Offset'!V4 -> 7.9 | DL2: m WL | DM2: h = | DN2: =(DK2-DH2)/2 -> 0.35 | DO2: m | DR2: ST | DS2: X | DT2: ='Tabel Offset'!V4 -> 7.9 | DU2: m WL | DV2: ~ | DW2: Zmax | DX2: m WL | ED2: m
D3: =D2 -> 0 | E3: m WL | F3: =(G2-D2)/2+D2 -> 0.25 | G3: m WL | H3: =G2 -> 0.5 | I3: m WL | J3: ΣYS | K3: A | L3: ATOTAL | P3: =P2 -> 0.5 | Q3: m WL | R3: =(S2-P2)/2+P2 -> 0.75 | S3: m WL | T3: =S2 -> 1 | U3: m WL | V3: ΣYS | W3: A | X3: ATOTAL | AB3: =AB2 -> 1 | AC3: m WL | AD3: =(AE2-AB2)/2+AB2 -> 1.5 | AE3: m WL | AF3: =AE2 -> 2 | AG3: m WL | AH3: ΣYS | AI3: A | AJ3: ATOTAL | AN3: =AN2 -> 2 | AO3: m WL | AP3: =(AQ2-AN2)/2+AN2 -> 2.5 | AQ3: m WL | AR3: =AQ2 -> 3 | AS3: m WL | AT3: ΣYS | AU3: A | AV3: ATOTAL | AZ3: =AZ2 -> 3 | BA3: m WL | BB3: =(BC2-AZ2)/2+AZ2 -> 3.5 | BC3: m WL | BD3: =BC2 -> 4 | BE3: m WL | BF3: ΣYS | BG3: A | BH3: ATOTAL | BL3: =BL2 -> 4 | BM3: m WL | BN3: =(BO2-BL2)/2+BL2 -> 4.5 | BO3: m WL | BP3: =BO2 -> 5 | BQ3: m WL | BR3: ΣYS | BS3: A | BT3: ATOTAL | BX3: =BX2 -> 5 | BY3: m WL | BZ3: =(CA2-BX2)/2+BX2 -> 5.5 | CA3: m WL | CB3: =CA2 -> 6 | CC3: m WL | CD3: ΣYS | CE3: A | CF3: ATOTAL | CJ3: =CJ2 -> 6 | CK3: m WL | CL3: =(CM2-CJ2)/2+CJ2 -> 6.25 | CM3: m WL | CN3: =CM2 -> 6.5 | CO3: m WL | CP3: ΣYS | CQ3: A | CR3: ATOTAL | CV3: =CV2 -> 6.5 | CW3: m WL | CX3: =(CY2-CV2)/2+CV2 -> 6.85 | CY3: m WL | CZ3: =CY2 -> 7.2 | DA3: m WL | DB3: ΣYS | DC3: A | DD3: ATOTAL | DH3: =DH2 -> 7.2 | DI3: m WL | DJ3: =(DK2-DH2)/2+DH2 -> 7.55 | DK3: m WL | DL3: =DK2 -> 7.9 | DM3: m WL | DN3: ΣYS | DO3: A | DP3: ATOTAL | DT3: =DT2 -> 7.9 | DU3: m WL | DV3: (Z-WL terakhir)/2+WL Terakhir | DY3: Zmax | EB3: ΣYS | EC3: A | ED3: ATOTAL
D4: S = | E4: 1 | F4: S = | G4: 4 | H4: S = | I4: 1 | P4: S = | Q4: 1 | R4: S = | S4: 4 | T4: S = | U4: 1 | AB4: S = | AC4: 1 | AD4: S = | AE4: 4 | AF4: S = | AG4: 1 | AN4: S = | AO4: 1 | AP4: S = | AQ4: 4 | AR4: S = | AS4: 1 | AZ4: S = | BA4: 1 | BB4: S = | BC4: 4 | BD4: S = | BE4: 1 | BL4: S = | BM4: 1 | BN4: S = | BO4: 4 | BP4: S = | BQ4: 1 | BX4: S = | BY4: 1 | BZ4: S = | CA4: 4 | CB4: S = | CC4: 1 | CJ4: S = | CK4: 1 | CL4: S = | CM4: 4 | CN4: S = | CO4: 1 | CV4: S = | CW4: 1 | CX4: S = | CY4: 4 | CZ4: S = | DA4: 1 | DH4: S = | DI4: 1 | DJ4: S = | DK4: 4 | DL4: S = | DM4: 1 | DT4: S = | DU4: 1 | DV4: S = | DW4: 4 | DX4: =DV3 -> (Z-WL terakhir)/2+WL Terakhir | DY4: S = | DZ4: 1 | EA4: Zmax
D5: Y | E5: YS | F5: Y | G5: YS | H5: Y | I5: YS | P5: Y | Q5: YS | R5: Y | S5: YS | T5: Y | U5: YS | AB5: Y | AC5: YS | AD5: Y | AE5: YS | AF5: Y | AG5: YS | AN5: Y | AO5: YS | AP5: Y | AQ5: YS | AR5: Y | AS5: YS | AZ5: Y | BA5: YS | BB5: Y | BC5: YS | BD5: Y | BE5: YS | BL5: Y | BM5: YS | BN5: Y | BO5: YS | BP5: Y | BQ5: YS | BX5: Y | BY5: YS | BZ5: Y | CA5: YS | CB5: Y | CC5: YS | CJ5: Y | CK5: YS | CL5: Y | CM5: YS | CN5: Y | CO5: YS | CV5: Y | CW5: YS | CX5: Y | CY5: YS | CZ5: Y | DA5: YS | DH5: Y | DI5: YS | DJ5: Y | DK5: YS | DL5: Y | DM5: YS | DT5: Y | DU5: YS | DV5: Y | DW5: YS | DY5: Y | DZ5: YS
B6: ='Tabel Offset'!$A7 -> AP | C6: =IF(B6="AP",0,IF(B6="FP",'Tabel Offset'!$AA$4,B6/20*'Tabel Offset'!$AA$4)) -> 0 | D6: ='Tabel Offset'!B7 -> 0 | E6: =D6*E$4 -> 0 | F6: ='Tabel Offset'!C7 -> 0 | G6: =F6*G$4 -> 0 | H6: ='Tabel Offset'!D7 -> 0 | I6: =H6*I$4 -> 0 | J6: =SUM(E6,G6,I6) -> 0 | K6: =2*1/3*J$2*J6 -> 0 | L6: =K6 -> 0 | N6: ='Tabel Offset'!$A7 -> AP | O6: =IF(N6="AP",0,IF(N6="FP",'Tabel Offset'!$AA$4,N6/20*'Tabel Offset'!$AA$4)) -> 0 | P6: ='Tabel Offset'!D5 -> 0 | Q6: =P6*Q$4 -> 0 | R6: ='Tabel Offset'!E7 -> 0 | S6: =R6*S$4 -> 0 | T6: ='Tabel Offset'!F7 -> 0 | U6: =T6*U$4 -> 0 | V6: =SUM(Q6,S6,U6) -> 0 | W6: =2*1/3*V$2*V6 -> 0 | X6: =W6+L6 -> 0 | Z6: ='Tabel Offset'!$A7 -> AP | AA6: =IF(Z6="AP",0,IF(Z6="FP",'Tabel Offset'!$AA$4,Z6/20*'Tabel Offset'!$AA$4)) -> 0 | AB6: ='Tabel Offset'!F7 -> 0 | AC6: =AB6*AC$4 -> 0 | AD6: ='Tabel Offset'!G7 -> 0 | AE6: =AD6*AE$4 -> 0 | AF6: ='Tabel Offset'!H7 -> 0 | AG6: =AF6*AG$4 -> 0 | AH6: =SUM(AC6,AE6,AG6) -> 0 | AI6: =2*1/3*AH$2*AH6 -> 0 | AJ6: =AI6+X6 -> 0 | AL6: ='Tabel Offset'!$A7 -> AP | AM6: =IF(AL6="AP",0,IF(AL6="FP",'Tabel Offset'!$AA$4,AL6/20*'Tabel Offset'!$AA$4)) -> 0 | AN6: ='Tabel Offset'!H7 -> 0 | AO6: =AN6*AO$4 -> 0 | AP6: ='Tabel Offset'!I7 -> 0 | AQ6: =AP6*AQ$4 -> 0 | AR6: ='Tabel Offset'!J7 -> 0 | AS6: =AR6*AS$4 -> 0 | AT6: =SUM(AO6,AQ6,AS6) -> 0 | AU6: =2*1/3*AT$2*AT6 -> 0 | AV6: =AU6+AJ6 -> 0 | AX6: ='Tabel Offset'!$A7 -> AP | AY6: =IF(AX6="AP",0,IF(AX6="FP",'Tabel Offset'!$AA$4,AX6/20*'Tabel Offset'!$AA$4)) -> 0 | AZ6: ='Tabel Offset'!J7 -> 0 | BA6: =AZ6*BA$4 -> 0 | BB6: ='Tabel Offset'!K7 -> 0 | BC6: =BB6*BC$4 -> 0 | BD6: ='Tabel Offset'!L7 -> 0 | BE6: =BD6*BE$4 -> 0 | BF6: =SUM(BA6,BC6,BE6) -> 0 | BG6: =2*1/3*BF$2*BF6 -> 0 | BH6: =BG6+AV6 -> 0 | BJ6: ='Tabel Offset'!$A7 -> AP | BK6: =IF(BJ6="AP",0,IF(BJ6="FP",'Tabel Offset'!$AA$4,BJ6/20*'Tabel Offset'!$AA$4)) -> 0 | BL6: ='Tabel Offset'!L7 -> 0 | BM6: =BL6*BM$4 -> 0 | BN6: ='Tabel Offset'!M7 -> 0 | BO6: =BN6*BO$4 -> 0 | BP6: ='Tabel Offset'!N7 -> 0 | BQ6: =BP6*BQ$4 -> 0 | BR6: =SUM(BM6,BO6,BQ6) -> 0 | BS6: =2*1/3*BR$2*BR6 -> 0 | BT6: =BS6+BH6 -> 0 | BV6: ='Tabel Offset'!$A7 -> AP | BW6: =IF(BV6="AP",0,IF(BV6="FP",'Tabel Offset'!$AA$4,BV6/20*'Tabel Offset'!$AA$4)) -> 0 | BX6: ='Tabel Offset'!N7 -> 0 | BY6: =BX6*BY$4 -> 0 | BZ6: ='Tabel Offset'!O7 -> 0.6606 | CA6: =BZ6*CA$4 -> 2.6424 | CB6: ='Tabel Offset'!P7 -> 1.652 | CC6: =CB6*CC$4 -> 1.652 | CD6: =SUM(BY6,CA6,CC6) -> 4.2944 | CE6: =2*1/3*CD$2*CD6 -> 1.4314667 | CF6: =CE6+BT6 -> 1.4314667 | CH6: ='Tabel Offset'!$A7 -> AP | CI6: =IF(CH6="AP",0,IF(CH6="FP",'Tabel Offset'!$AA$4,CH6/20*'Tabel Offset'!$AA$4)) -> 0 | CJ6: ='Tabel Offset'!P7 -> 1.652 | CK6: =CJ6*CK$4 -> 1.652 | CL6: ='Tabel Offset'!Q7 -> 2.0552 | CM6: =CL6*CM$4 -> 8.2208 | CN6: ='Tabel Offset'!R7 -> 2.442 | CO6: =CN6*CO$4 -> 2.442 | CP6: =SUM(CK6,CM6,CO6) -> 12.3148 | CQ6: =2*1/3*CP$2*CP6 -> 2.0524667 | CR6: =CQ6+CF6 -> 3.4839333 | CT6: ='Tabel Offset'!$A7 -> AP | CU6: =IF(CT6="AP",0,IF(CT6="FP",'Tabel Offset'!$AA$4,CT6/20*'Tabel Offset'!$AA$4)) -> 0 | CV6: ='Tabel Offset'!R7 -> 2.442 | CW6: =CV6*CW$4 -> 2.442 | CX6: ='Tabel Offset'!S7 -> 2.9635 | CY6: =CX6*CY$4 -> 11.854 | CZ6: ='Tabel Offset'!T7 -> 3.4637 | DA6: =CZ6*DA$4 -> 3.4637 | DB6: =SUM(CW6,CY6,DA6) -> 17.7597 | DC6: =2*1/3*DB$2*DB6 -> 4.14393 | DD6: =DC6+CR6 -> 7.6278633 | DF6: ='Tabel Offset'!$A7 -> AP | DG6: =IF(DF6="AP",0,IF(DF6="FP",'Tabel Offset'!$AA$4,DF6/20*'Tabel Offset'!$AA$4)) -> 0 | DH6: ='Tabel Offset'!T7 -> 3.4637 | DI6: =DH6*DI$4 -> 3.4637 | DJ6: ='Tabel Offset'!U7 -> 3.9378 | DK6: =DJ6*DK$4 -> 15.7512 | DL6: ='Tabel Offset'!V7 -> 4.381 | DM6: =DL6*DM$4 -> 4.381 | DN6: =SUM(DI6,DK6,DM6) -> 23.5959 | DO6: =2*1/3*DN$2*DN6 -> 5.50571 | DP6: =DO6+DD6 -> 13.133573 | DR6: ='Tabel Offset'!$A7 -> AP | DS6: =IF(DR6="AP",0,IF(DR6="FP",'Tabel Offset'!$AA$4,DR6/20*'Tabel Offset'!$AA$4)) -> 0 | DT6: ='Tabel Offset'!V7 -> 4.381 | DU6: =DT6*DU$4 -> 4.381 | DV6: 5.0116 | DW6: =DV6*DW$4 -> 20.0464 | DX6: =(EA6-DT$2)/2+DT$2 -> 8.39725 | DY6: 5.211 | DZ6: =DY6*DZ$4 -> 5.211 | EA6: 8.8945 | EB6: =SUM(DU6,DW6,DZ6) -> 29.6384 | EC6: =2*1/3*((EA6-DT$2)/2)*EB6 -> 9.8251296 | ED6: =EC6+DP6 -> 22.958703
B7: ='Tabel Offset'!$A8 -> 0.5 | C7: =IF(B7="AP",0,IF(B7="FP",'Tabel Offset'!$AA$4,B7/20*'Tabel Offset'!$AA$4)) -> 2.37675 | D7: ='Tabel Offset'!B8 -> 0 | E7: =D7*E$4 -> 0 | F7: ='Tabel Offset'!C8 -> 0 | G7: =F7*G$4 -> 0 | H7: ='Tabel Offset'!D8 -> 0 | I7: =H7*I$4 -> 0 | J7: =SUM(E7,G7,I7) -> 0 | K7: =2*1/3*J$2*J7 -> 0 | L7: =K7 -> 0 | N7: ='Tabel Offset'!$A8 -> 0.5 | O7: =IF(N7="AP",0,IF(N7="FP",'Tabel Offset'!$AA$4,N7/20*'Tabel Offset'!$AA$4)) -> 2.37675 | P7: ='Tabel Offset'!D8 -> 0 | Q7: =P7*Q$4 -> 0 | R7: ='Tabel Offset'!E8 -> 0 | S7: =R7*S$4 -> 0 | T7: ='Tabel Offset'!F8 -> 0.126 | U7: =T7*U$4 -> 0.126 | V7: =SUM(Q7,S7,U7) -> 0.126 | W7: =2*1/3*V$2*V7 -> 0.021 | X7: =W7+L7 -> 0.021 | Z7: ='Tabel Offset'!$A8 -> 0.5 | AA7: =IF(Z7="AP",0,IF(Z7="FP",'Tabel Offset'!$AA$4,Z7/20*'Tabel Offset'!$AA$4)) -> 2.37675 | AB7: ='Tabel Offset'!F8 -> 0.126 | AC7: =AB7*AC$4 -> 0.126 | AD7: ='Tabel Offset'!G8 -> 0.408 | AE7: =AD7*AE$4 -> 1.632 | AF7: ='Tabel Offset'!H8 -> 0.579 | AG7: =AF7*AG$4 -> 0.579 | AH7: =SUM(AC7,AE7,AG7) -> 2.337 | AI7: =2*1/3*AH$2*AH7 -> 0.779 | AJ7: =AI7+X7 -> 0.8 | AL7: ='Tabel Offset'!$A8 -> 0.5 | AM7: =IF(AL7="AP",0,IF(AL7="FP",'Tabel Offset'!$AA$4,AL7/20*'Tabel Offset'!$AA$4)) -> 2.37675 | AN7: ='Tabel Offset'!H8 -> 0.579 | AO7: =AN7*AO$4 -> 0.579 | AP7: ='Tabel Offset'!I8 -> 0.726 | AQ7: =AP7*AQ$4 -> 2.904 | AR7: ='Tabel Offset'!J8 -> 0.8416 | AS7: =AR7*AS$4 -> 0.8416 | AT7: =SUM(AO7,AQ7,AS7) -> 4.3246 | AU7: =2*1/3*AT$2*AT7 -> 1.4415333 | AV7: =AU7+AJ7 -> 2.2415333 | AX7: ='Tabel Offset'!$A8 -> 0.5 | AY7: =IF(AX7="AP",0,IF(AX7="FP",'Tabel Offset'!$AA$4,AX7/20*'Tabel Offset'!$AA$4)) -> 2.37675 | AZ7: ='Tabel Offset'!J8 -> 0.8416 | BA7: =AZ7*BA$4 -> 0.8416 | BB7: ='Tabel Offset'!K8 -> 0.9278 | BC7: =BB7*BC$4 -> 3.7112 | BD7: ='Tabel Offset'!L8 -> 1.0852 | BE7: =BD7*BE$4 -> 1.0852 | BF7: =SUM(BA7,BC7,BE7) -> 5.638 | BG7: =2*1/3*BF$2*BF7 -> 1.8793333 | BH7: =BG7+AV7 -> 4.1208667 | BJ7: ='Tabel Offset'!$A8 -> 0.5 | BK7: =IF(BJ7="AP",0,IF(BJ7="FP",'Tabel Offset'!$AA$4,BJ7/20*'Tabel Offset'!$AA$4)) -> 2.37675 | BL7: ='Tabel Offset'!L8 -> 1.0852 | BM7: =BL7*BM$4 -> 1.0852 | BN7: ='Tabel Offset'!M8 -> 1.4456 | BO7: =BN7*BO$4 -> 5.7824 | BP7: ='Tabel Offset'!N8 -> 1.9207 | BQ7: =BP7*BQ$4 -> 1.9207 | BR7: =SUM(BM7,BO7,BQ7) -> 8.7883 | BS7: =2*1/3*BR$2*BR7 -> 2.9294333 | BT7: =BS7+BH7 -> 7.0503 | BV7: ='Tabel Offset'!$A8 -> 0.5 | BW7: =IF(BV7="AP",0,IF(BV7="FP",'Tabel Offset'!$AA$4,BV7/20*'Tabel Offset'!$AA$4)) -> 2.37675 | BX7: ='Tabel Offset'!N8 -> 1.9207 | BY7: =BX7*BY$4 -> 1.9207 | BZ7: ='Tabel Offset'!O8 -> 2.4032 | CA7: =BZ7*CA$4 -> 9.6128 | CB7: ='Tabel Offset'!P8 -> 2.9306 | CC7: =CB7*CC$4 -> 2.9306 | CD7: =SUM(BY7,CA7,CC7) -> 14.4641 | CE7: =2*1/3*CD$2*CD7 -> 4.8213667 | CF7: =CE7+BT7 -> 11.871667 | CH7: ='Tabel Offset'!$A8 -> 0.5 | CI7: =IF(CH7="AP",0,IF(CH7="FP",'Tabel Offset'!$AA$4,CH7/20*'Tabel Offset'!$AA$4)) -> 2.37675 | CJ7: ='Tabel Offset'!P8 -> 2.9306 | CK7: =CJ7*CK$4 -> 2.9306 | CL7: ='Tabel Offset'!Q8 -> 3.2115 | CM7: =CL7*CM$4 -> 12.846 | CN7: ='Tabel Offset'!R8 -> 3.5166 | CO7: =CN7*CO$4 -> 3.5166 | CP7: =SUM(CK7,CM7,CO7) -> 19.2932 | CQ7: =2*1/3*CP$2*CP7 -> 3.2155333 | CR7: =CQ7+CF7 -> 15.0872 | CT7: ='Tabel Offset'!$A8 -> 0.5 | CU7: =IF(CT7="AP",0,IF(CT7="FP",'Tabel Offset'!$AA$4,CT7/20*'Tabel Offset'!$AA$4)) -> 2.37675 | CV7: ='Tabel Offset'!R8 -> 3.5166 | CW7: =CV7*CW$4 -> 3.5166 | CX7: ='Tabel Offset'!S8 -> 3.9625 | CY7: =CX7*CY$4 -> 15.85 | CZ7: ='Tabel Offset'!T8 -> 4.3792 | DA7: =CZ7*DA$4 -> 4.3792 | DB7: =SUM(CW7,CY7,DA7) -> 23.7458 | DC7: =2*1/3*DB$2*DB7 -> 5.5406867 | DD7: =DC7+CR7 -> 20.627887 | DF7: ='Tabel Offset'!$A8 -> 0.5 | DG7: =IF(DF7="AP",0,IF(DF7="FP",'Tabel Offset'!$AA$4,DF7/20*'Tabel Offset'!$AA$4)) -> 2.37675 | DH7: ='Tabel Offset'!T8 -> 4.3792 | DI7: =DH7*DI$4 -> 4.3792 | DJ7: ='Tabel Offset'!U8 -> 4.7765 | DK7: =DJ7*DK$4 -> 19.106 | DL7: ='Tabel Offset'!V8 -> 5.1792 | DM7: =DL7*DM$4 -> 5.1792 | DN7: =SUM(DI7,DK7,DM7) -> 28.6644 | DO7: =2*1/3*DN$2*DN7 -> 6.68836 | DP7: =DO7+DD7 -> 27.316247 | DR7: ='Tabel Offset'!$A8 -> 0.5 | DS7: =IF(DR7="AP",0,IF(DR7="FP",'Tabel Offset'!$AA$4,DR7/20*'Tabel Offset'!$AA$4)) -> 2.37675 | DT7: ='Tabel Offset'!V8 -> 5.1792 | DU7: =DT7*DU$4 -> 5.1792 | DV7: 5.7396 | DW7: =DV7*DW$4 -> 22.9584 | DX7: =(EA7-DT$2)/2+DT$2 -> 8.35375 | DY7: 5.66 | DZ7: =DY7*DZ$4 -> 5.66 | EA7: 8.8075 | EB7: =SUM(DU7,DW7,DZ7) -> 33.7976 | EC7: =2*1/3*((EA7-DT$2)/2)*EB7 -> 10.223774 | ED7: =EC7+DP7 -> 37.540021
B8: ='Tabel Offset'!$A9 -> 1 | C8: =IF(B8="AP",0,IF(B8="FP",'Tabel Offset'!$AA$4,B8/20*'Tabel Offset'!$AA$4)) -> 4.7535 | D8: ='Tabel Offset'!B9 -> 0 | E8: =D8*E$4 -> 0 | F8: ='Tabel Offset'!C9 -> 0.2612 | G8: =F8*G$4 -> 1.0448 | H8: ='Tabel Offset'!D9 -> 0.5213 | I8: =H8*I$4 -> 0.5213 | J8: =SUM(E8,G8,I8) -> 1.5661 | K8: =2*1/3*J$2*J8 -> 0.26101667 | L8: =K8 -> 0.26101667 | N8: ='Tabel Offset'!$A9 -> 1 | O8: =IF(N8="AP",0,IF(N8="FP",'Tabel Offset'!$AA$4,N8/20*'Tabel Offset'!$AA$4)) -> 4.7535 | P8: ='Tabel Offset'!D9 -> 0.5213 | Q8: =P8*Q$4 -> 0.5213 | R8: ='Tabel Offset'!E9 -> 0.7287 | S8: =R8*S$4 -> 2.9148 | T8: ='Tabel Offset'!F9 -> 0.908 | U8: =T8*U$4 -> 0.908 | V8: =SUM(Q8,S8,U8) -> 4.3441 | W8: =2*1/3*V$2*V8 -> 0.72401667 | X8: =W8+L8 -> 0.98503333 | Z8: ='Tabel Offset'!$A9 -> 1 | AA8: =IF(Z8="AP",0,IF(Z8="FP",'Tabel Offset'!$AA$4,Z8/20*'Tabel Offset'!$AA$4)) -> 4.7535 | AB8: ='Tabel Offset'!F9 -> 0.908 | AC8: =AB8*AC$4 -> 0.908 | AD8: ='Tabel Offset'!G9 -> 1.2141 | AE8: =AD8*AE$4 -> 4.8564 | AF8: ='Tabel Offset'!H9 -> 1.4761 | AG8: =AF8*AG$4 -> 1.4761 | AH8: =SUM(AC8,AE8,AG8) -> 7.2405 | AI8: =2*1/3*AH$2*AH8 -> 2.4135 | AJ8: =AI8+X8 -> 3.3985333 | AL8: ='Tabel Offset'!$A9 -> 1 | AM8: =IF(AL8="AP",0,IF(AL8="FP",'Tabel Offset'!$AA$4,AL8/20*'Tabel Offset'!$AA$4)) -> 4.7535 | AN8: ='Tabel Offset'!H9 -> 1.4761 | AO8: =AN8*AO$4 -> 1.4761 | AP8: ='Tabel Offset'!I9 -> 1.7167 | AQ8: =AP8*AQ$4 -> 6.8668 | AR8: ='Tabel Offset'!J8 -> 0.8416 | AS8: =AR8*AS$4 -> 0.8416 | AT8: =SUM(AO8,AQ8,AS8) -> 9.1845 | AU8: =2*1/3*AT$2*AT8 -> 3.0615 | AV8: =AU8+AJ8 -> 6.4600333 | AX8: ='Tabel Offset'!$A9 -> 1 | AY8: =IF(AX8="AP",0,IF(AX8="FP",'Tabel Offset'!$AA$4,AX8/20*'Tabel Offset'!$AA$4)) -> 4.7535 | AZ8: ='Tabel Offset'!J9 -> 1.9563 | BA8: =AZ8*BA$4 -> 1.9563 | BB8: ='Tabel Offset'!K9 -> 2.2093 | BC8: =BB8*BC$4 -> 8.8372 | BD8: ='Tabel Offset'!L9 -> 2.4785 | BE8: =BD8*BE$4 -> 2.4785 | BF8: =SUM(BA8,BC8,BE8) -> 13.272 | BG8: =2*1/3*BF$2*BF8 -> 4.424 | BH8: =BG8+AV8 -> 10.884033 | BJ8: ='Tabel Offset'!$A9 -> 1 | BK8: =IF(BJ8="AP",0,IF(BJ8="FP",'Tabel Offset'!$AA$4,BJ8/20*'Tabel Offset'!$AA$4)) -> 4.7535 | BL8: ='Tabel Offset'!L9 -> 2.4785 | BM8: =BL8*BM$4 -> 2.4785 | BN8: ='Tabel Offset'!M9 -> 2.7705 | BO8: =BN8*BO$4 -> 11.082 | BP8: ='Tabel Offset'!N9 -> 3.1349 | BQ8: =BP8*BQ$4 -> 3.1349 | BR8: =SUM(BM8,BO8,BQ8) -> 16.6954 | BS8: =2*1/3*BR$2*BR8 -> 5.5651333 | BT8: =BS8+BH8 -> 16.449167 | BV8: ='Tabel Offset'!$A9 -> 1 | BW8: =IF(BV8="AP",0,IF(BV8="FP",'Tabel Offset'!$AA$4,BV8/20*'Tabel Offset'!$AA$4)) -> 4.7535 | BX8: ='Tabel Offset'!N9 -> 3.1349 | BY8: =BX8*BY$4 -> 3.1349 | BZ8: ='Tabel Offset'!O9 -> 3.5859 | CA8: =BZ8*CA$4 -> 14.3436 | CB8: ='Tabel Offset'!P9 -> 4.0891 | CC8: =CB8*CC$4 -> 4.0891 | CD8: =SUM(BY8,CA8,CC8) -> 21.5676 | CE8: =2*1/3*CD$2*CD8 -> 7.1892 | CF8: =CE8+BT8 -> 23.638367 | CH8: ='Tabel Offset'!$A9 -> 1 | CI8: =IF(CH8="AP",0,IF(CH8="FP",'Tabel Offset'!$AA$4,CH8/20*'Tabel Offset'!$AA$4)) -> 4.7535 | CJ8: ='Tabel Offset'!P9 -> 4.0891 | CK8: =CJ8*CK$4 -> 4.0891 | CL8: ='Tabel Offset'!Q9 -> 4.3596 | CM8: =CL8*CM$4 -> 17.4384 | CN8: ='Tabel Offset'!R9 -> 4.6355 | CO8: =CN8*CO$4 -> 4.6355 | CP8: =SUM(CK8,CM8,CO8) -> 26.163 | CQ8: =2*1/3*CP$2*CP8 -> 4.3605 | CR8: =CQ8+CF8 -> 27.998867 | CT8: ='Tabel Offset'!$A9 -> 1 | CU8: =IF(CT8="AP",0,IF(CT8="FP",'Tabel Offset'!$AA$4,CT8/20*'Tabel Offset'!$AA$4)) -> 4.7535 | CV8: ='Tabel Offset'!R9 -> 4.6355 | CW8: =CV8*CW$4 -> 4.6355 | CX8: ='Tabel Offset'!S9 -> 5.0395 | CY8: =CX8*CY$4 -> 20.158 | CZ8: ='Tabel Offset'!T9 -> 5.4706 | DA8: =CZ8*DA$4 -> 5.4706 | DB8: =SUM(CW8,CY8,DA8) -> 30.2641 | DC8: =2*1/3*DB$2*DB8 -> 7.0616233 | DD8: =DC8+CR8 -> 35.06049 | DF8: ='Tabel Offset'!$A9 -> 1 | DG8: =IF(DF8="AP",0,IF(DF8="FP",'Tabel Offset'!$AA$4,DF8/20*'Tabel Offset'!$AA$4)) -> 4.7535 | DH8: ='Tabel Offset'!T9 -> 5.4706 | DI8: =DH8*DI$4 -> 5.4706 | DJ8: ='Tabel Offset'!U9 -> 5.8748 | DK8: =DJ8*DK$4 -> 23.4992 | DL8: ='Tabel Offset'!V9 -> 6.207 | DM8: =DL8*DM$4 -> 6.207 | DN8: =SUM(DI8,DK8,DM8) -> 35.1768 | DO8: =2*1/3*DN$2*DN8 -> 8.20792 | DP8: =DO8+DD8 -> 43.26841 | DR8: ='Tabel Offset'!$A9 -> 1 | DS8: =IF(DR8="AP",0,IF(DR8="FP",'Tabel Offset'!$AA$4,DR8/20*'Tabel Offset'!$AA$4)) -> 4.7535 | DT8: ='Tabel Offset'!V9 -> 6.207 | DU8: =DT8*DU$4 -> 6.207 | DV8: 6.5424 | DW8: =DV8*DW$4 -> 26.1696 | DX8: =(EA8-DT$2)/2+DT$2 -> 8.31045 | DY8: 5.64 | DZ8: =DY8*DZ$4 -> 5.64 | EA8: 8.7209 | EB8: =SUM(DU8,DW8,DZ8) -> 38.0166 | EC8: =2*1/3*((EA8-DT$2)/2)*EB8 -> 10.402609 | ED8: =EC8+DP8 -> 53.671019
B9: ='Tabel Offset'!$A10 -> 1.5 | C9: =IF(B9="AP",0,IF(B9="FP",'Tabel Offset'!$AA$4,B9/20*'Tabel Offset'!$AA$4)) -> 7.13025 | D9: ='Tabel Offset'!B10 -> 0.018 | E9: =D9*E$4 -> 0.018 | F9: ='Tabel Offset'!C10 -> 0.6839 | G9: =F9*G$4 -> 2.7356 | H9: ='Tabel Offset'!D10 -> 1.0291 | I9: =H9*I$4 -> 1.0291 | J9: =SUM(E9,G9,I9) -> 3.7827 | K9: =2*1/3*J$2*J9 -> 0.63045 | L9: =K9 -> 0.63045 | N9: ='Tabel Offset'!$A10 -> 1.5 | O9: =IF(N9="AP",0,IF(N9="FP",'Tabel Offset'!$AA$4,N9/20*'Tabel Offset'!$AA$4)) -> 7.13025 | P9: ='Tabel Offset'!D10 -> 1.0291 | Q9: =P9*Q$4 -> 1.0291 | R9: ='Tabel Offset'!E10 -> 1.2899 | S9: =R9*S$4 -> 5.1596 | T9: ='Tabel Offset'!F10 -> 1.5044 | U9: =T9*U$4 -> 1.5044 | V9: =SUM(Q9,S9,U9) -> 7.6931 | W9: =2*1/3*V$2*V9 -> 1.2821833 | X9: =W9+L9 -> 1.9126333 | Z9: ='Tabel Offset'!$A10 -> 1.5 | AA9: =IF(Z9="AP",0,IF(Z9="FP",'Tabel Offset'!$AA$4,Z9/20*'Tabel Offset'!$AA$4)) -> 7.13025 | AB9: ='Tabel Offset'!F10 -> 1.5044 | AC9: =AB9*AC$4 -> 1.5044 | AD9: ='Tabel Offset'!G10 -> 1.859 | AE9: =AD9*AE$4 -> 7.436 | AF9: ='Tabel Offset'!H10 -> 2.1913 | AG9: =AF9*AG$4 -> 2.1913 | AH9: =SUM(AC9,AE9,AG9) -> 11.1317 | AI9: =2*1/3*AH$2*AH9 -> 3.7105667 | AJ9: =AI9+X9 -> 5.6232 | AL9: ='Tabel Offset'!$A10 -> 1.5 | AM9: =IF(AL9="AP",0,IF(AL9="FP",'Tabel Offset'!$AA$4,AL9/20*'Tabel Offset'!$AA$4)) -> 7.13025 | AN9: ='Tabel Offset'!H10 -> 2.1913 | AO9: =AN9*AO$4 -> 2.1913 | AP9: ='Tabel Offset'!I10 -> 2.5159 | AQ9: =AP9*AQ$4 -> 10.0636 | AR9: ='Tabel Offset'!J9 -> 1.9563 | AS9: =AR9*AS$4 -> 1.9563 | AT9: =SUM(AO9,AQ9,AS9) -> 14.2112 | AU9: =2*1/3*AT$2*AT9 -> 4.7370667 | AV9: =AU9+AJ9 -> 10.360267 | AX9: ='Tabel Offset'!$A10 -> 1.5 | AY9: =IF(AX9="AP",0,IF(AX9="FP",'Tabel Offset'!$AA$4,AX9/20*'Tabel Offset'!$AA$4)) -> 7.13025 | AZ9: ='Tabel Offset'!J10 -> 2.8159 | BA9: =AZ9*BA$4 -> 2.8159 | BB9: ='Tabel Offset'!K10 -> 3.1036 | BC9: =BB9*BC$4 -> 12.4144 | BD9: ='Tabel Offset'!L10 -> 3.4388 | BE9: =BD9*BE$4 -> 3.4388 | BF9: =SUM(BA9,BC9,BE9) -> 18.6691 | BG9: =2*1/3*BF$2*BF9 -> 6.2230333 | BH9: =BG9+AV9 -> 16.5833 | BJ9: ='Tabel Offset'!$A10 -> 1.5 | BK9: =IF(BJ9="AP",0,IF(BJ9="FP",'Tabel Offset'!$AA$4,BJ9/20*'Tabel Offset'!$AA$4)) -> 7.13025 | BL9: ='Tabel Offset'!L10 -> 3.4388 | BM9: =BL9*BM$4 -> 3.4388 | BN9: ='Tabel Offset'!M10 -> 3.8023 | BO9: =BN9*BO$4 -> 15.2092 | BP9: ='Tabel Offset'!N10 -> 4.2317 | BQ9: =BP9*BQ$4 -> 4.2317 | BR9: =SUM(BM9,BO9,BQ9) -> 22.8797 | BS9: =2*1/3*BR$2*BR9 -> 7.6265667 | BT9: =BS9+BH9 -> 24.209867 | BV9: ='Tabel Offset'!$A10 -> 1.5 | BW9: =IF(BV9="AP",0,IF(BV9="FP",'Tabel Offset'!$AA$4,BV9/20*'Tabel Offset'!$AA$4)) -> 7.13025 | BX9: ='Tabel Offset'!N10 -> 4.2317 | BY9: =BX9*BY$4 -> 4.2317 | BZ9: ='Tabel Offset'!O10 -> 4.725 | CA9: =BZ9*CA$4 -> 18.9 | CB9: ='Tabel Offset'!P10 -> 5.2425 | CC9: =CB9*CC$4 -> 5.2425 | CD9: =SUM(BY9,CA9,CC9) -> 28.3742 | CE9: =2*1/3*CD$2*CD9 -> 9.4580667 | CF9: =CE9+BT9 -> 33.667933 | CH9: ='Tabel Offset'!$A10 -> 1.5 | CI9: =IF(CH9="AP",0,IF(CH9="FP",'Tabel Offset'!$AA$4,CH9/20*'Tabel Offset'!$AA$4)) -> 7.13025 | CJ9: ='Tabel Offset'!P10 -> 5.2425 | CK9: =CJ9*CK$4 -> 5.2425 | CL9: ='Tabel Offset'!Q10 -> 5.5101 | CM9: =CL9*CM$4 -> 22.0404 | CN9: ='Tabel Offset'!R10 -> 5.788 | CO9: =CN9*CO$4 -> 5.788 | CP9: =SUM(CK9,CM9,CO9) -> 33.0709 | CQ9: =2*1/3*CP$2*CP9 -> 5.5118167 | CR9: =CQ9+CF9 -> 39.17975 | CT9: ='Tabel Offset'!$A10 -> 1.5 | CU9: =IF(CT9="AP",0,IF(CT9="FP",'Tabel Offset'!$AA$4,CT9/20*'Tabel Offset'!$AA$4)) -> 7.13025 | CV9: ='Tabel Offset'!R10 -> 5.788 | CW9: =CV9*CW$4 -> 5.788 | CX9: ='Tabel Offset'!S10 -> 8.141 | CY9: =CX9*CY$4 -> 32.564 | CZ9: ='Tabel Offset'!T10 -> 6.4225 | DA9: =CZ9*DA$4 -> 6.4225 | DB9: =SUM(CW9,CY9,DA9) -> 44.7745 | DC9: =2*1/3*DB$2*DB9 -> 10.447383 | DD9: =DC9+CR9 -> 49.627133 | DF9: ='Tabel Offset'!$A10 -> 1.5 | DG9: =IF(DF9="AP",0,IF(DF9="FP",'Tabel Offset'!$AA$4,DF9/20*'Tabel Offset'!$AA$4)) -> 7.13025 | DH9: ='Tabel Offset'!T10 -> 6.4225 | DI9: =DH9*DI$4 -> 6.4225 | DJ9: ='Tabel Offset'!U10 -> 6.654 | DK9: =DJ9*DK$4 -> 26.616 | DL9: ='Tabel Offset'!V10 -> 6.8489 | DM9: =DL9*DM$4 -> 6.8489 | DN9: =SUM(DI9,DK9,DM9) -> 39.8874 | DO9: =2*1/3*DN$2*DN9 -> 9.30706 | DP9: =DO9+DD9 -> 58.934193 | DR9: ='Tabel Offset'!$A10 -> 1.5 | DS9: =IF(DR9="AP",0,IF(DR9="FP",'Tabel Offset'!$AA$4,DR9/20*'Tabel Offset'!$AA$4)) -> 7.13025 | DT9: ='Tabel Offset'!V10 -> 6.8489 | DU9: =DT9*DU$4 -> 6.8489 | DV9: 7.0375 | DW9: =DV9*DW$4 -> 28.15 | DX9: =(EA9-DT$2)/2+DT$2 -> 8.26695 | DY9: 6.015 | DZ9: =DY9*DZ$4 -> 6.015 | EA9: 8.6339 | EB9: =SUM(DU9,DW9,DZ9) -> 41.0139 | EC9: =2*1/3*((EA9-DT$2)/2)*EB9 -> 10.033367 | ED9: =EC9+DP9 -> 68.96756
B10: ='Tabel Offset'!$A11 -> 2 | C10: =IF(B10="AP",0,IF(B10="FP",'Tabel Offset'!$AA$4,B10/20*'Tabel Offset'!$AA$4)) -> 9.507 | D10: ='Tabel Offset'!B11 -> 0.076 | E10: =D10*E$4 -> 0.076 | F10: ='Tabel Offset'!C11 -> 1.0672 | G10: =F10*G$4 -> 4.2688 | H10: ='Tabel Offset'!D11 -> 1.521 | I10: =H10*I$4 -> 1.521 | J10: =SUM(E10,G10,I10) -> 5.8658 | K10: =2*1/3*J$2*J10 -> 0.97763333 | L10: =K10 -> 0.97763333 | N10: ='Tabel Offset'!$A11 -> 2 | O10: =IF(N10="AP",0,IF(N10="FP",'Tabel Offset'!$AA$4,N10/20*'Tabel Offset'!$AA$4)) -> 9.507 | P10: ='Tabel Offset'!D11 -> 1.521 | Q10: =P10*Q$4 -> 1.521 | R10: ='Tabel Offset'!E11 -> 1.8553 | S10: =R10*S$4 -> 7.4212 | T10: ='Tabel Offset'!F11 -> 2.1235 | U10: =T10*U$4 -> 2.1235 | V10: =SUM(Q10,S10,U10) -> 11.0657 | W10: =2*1/3*V$2*V10 -> 1.8442833 | X10: =W10+L10 -> 2.8219167 | Z10: ='Tabel Offset'!$A11 -> 2 | AA10: =IF(Z10="AP",0,IF(Z10="FP",'Tabel Offset'!$AA$4,Z10/20*'Tabel Offset'!$AA$4)) -> 9.507 | AB10: ='Tabel Offset'!F11 -> 2.1235 | AC10: =AB10*AC$4 -> 2.1235 | AD10: ='Tabel Offset'!G11 -> 2.609 | AE10: =AD10*AE$4 -> 10.436 | AF10: ='Tabel Offset'!H11 -> 3.0713 | AG10: =AF10*AG$4 -> 3.0713 | AH10: =SUM(AC10,AE10,AG10) -> 15.6308 | AI10: =2*1/3*AH$2*AH10 -> 5.2102667 | AJ10: =AI10+X10 -> 8.0321833 | AL10: ='Tabel Offset'!$A11 -> 2 | AM10: =IF(AL10="AP",0,IF(AL10="FP",'Tabel Offset'!$AA$4,AL10/20*'Tabel Offset'!$AA$4)) -> 9.507 | AN10: ='Tabel Offset'!H11 -> 3.0713 | AO10: =AN10*AO$4 -> 3.0713 | AP10: ='Tabel Offset'!I11 -> 3.4531 | AQ10: =AP10*AQ$4 -> 13.8124 | AR10: ='Tabel Offset'!J10 -> 2.8159 | AS10: =AR10*AS$4 -> 2.8159 | AT10: =SUM(AO10,AQ10,AS10) -> 19.6996 | AU10: =2*1/3*AT$2*AT10 -> 6.5665333 | AV10: =AU10+AJ10 -> 14.598717 | AX10: ='Tabel Offset'!$A11 -> 2 | AY10: =IF(AX10="AP",0,IF(AX10="FP",'Tabel Offset'!$AA$4,AX10/20*'Tabel Offset'!$AA$4)) -> 9.507 | AZ10: ='Tabel Offset'!J11 -> 3.7939 | BA10: =AZ10*BA$4 -> 3.7939 | BB10: ='Tabel Offset'!K11 -> 4.132 | BC10: =BB10*BC$4 -> 16.528 | BD10: ='Tabel Offset'!L11 -> 4.4604 | BE10: =BD10*BE$4 -> 4.4604 | BF10: =SUM(BA10,BC10,BE10) -> 24.7823 | BG10: =2*1/3*BF$2*BF10 -> 8.2607667 | BH10: =BG10+AV10 -> 22.859483 | BJ10: ='Tabel Offset'!$A11 -> 2 | BK10: =IF(BJ10="AP",0,IF(BJ10="FP",'Tabel Offset'!$AA$4,BJ10/20*'Tabel Offset'!$AA$4)) -> 9.507 | BL10: ='Tabel Offset'!L11 -> 4.4604 | BM10: =BL10*BM$4 -> 4.4604 | BN10: ='Tabel Offset'!M11 -> 4.8564 | BO10: =BN10*BO$4 -> 19.4256 | BP10: ='Tabel Offset'!N11 -> 5.2958 | BQ10: =BP10*BQ$4 -> 5.2958 | BR10: =SUM(BM10,BO10,BQ10) -> 29.1818 | BS10: =2*1/3*BR$2*BR10 -> 9.7272667 | BT10: =BS10+BH10 -> 32.58675 | BV10: ='Tabel Offset'!$A11 -> 2 | BW10: =IF(BV10="AP",0,IF(BV10="FP",'Tabel Offset'!$AA$4,BV10/20*'Tabel Offset'!$AA$4)) -> 9.507 | BX10: ='Tabel Offset'!N11 -> 5.2958 | BY10: =BX10*BY$4 -> 5.2958 | BZ10: ='Tabel Offset'!O11 -> 5.75 | CA10: =BZ10*CA$4 -> 23 | CB10: ='Tabel Offset'!P11 -> 6.2245 | CC10: =CB10*CC$4 -> 6.2245 | CD10: =SUM(BY10,CA10,CC10) -> 34.5203 | CE10: =2*1/3*CD$2*CD10 -> 11.506767 | CF10: =CE10+BT10 -> 44.093517 | CH10: ='Tabel Offset'!$A11 -> 2 | CI10: =IF(CH10="AP",0,IF(CH10="FP",'Tabel Offset'!$AA$4,CH10/20*'Tabel Offset'!$AA$4)) -> 9.507 | CJ10: ='Tabel Offset'!P11 -> 6.2245 | CK10: =CJ10*CK$4 -> 6.2245 | CL10: ='Tabel Offset'!Q11 -> 6.444 | CM10: =CL10*CM$4 -> 25.776 | CN10: ='Tabel Offset'!R11 -> 6.6256 | CO10: =CN10*CO$4 -> 6.6256 | CP10: =SUM(CK10,CM10,CO10) -> 38.6261 | CQ10: =2*1/3*CP$2*CP10 -> 6.4376833 | CR10: =CQ10+CF10 -> 50.5312 | CT10: ='Tabel Offset'!$A11 -> 2 | CU10: =IF(CT10="AP",0,IF(CT10="FP",'Tabel Offset'!$AA$4,CT10/20*'Tabel Offset'!$AA$4)) -> 9.507 | CV10: ='Tabel Offset'!R11 -> 6.6256 | CW10: =CV10*CW$4 -> 6.6256 | CX10: ='Tabel Offset'!S11 -> 6.8285 | CY10: =CX10*CY$4 -> 27.314 | CZ10: ='Tabel Offset'!T11 -> 6.9941 | DA10: =CZ10*DA$4 -> 6.9941 | DB10: =SUM(CW10,CY10,DA10) -> 40.9337 | DC10: =2*1/3*DB$2*DB10 -> 9.5511967 | DD10: =DC10+CR10 -> 60.082397 | DF10: ='Tabel Offset'!$A11 -> 2 | DG10: =IF(DF10="AP",0,IF(DF10="FP",'Tabel Offset'!$AA$4,DF10/20*'Tabel Offset'!$AA$4)) -> 9.507 | DH10: ='Tabel Offset'!T11 -> 6.9941 | DI10: =DH10*DI$4 -> 6.9941 | DJ10: ='Tabel Offset'!U11 -> 7.1372 | DK10: =DJ10*DK$4 -> 28.5488 | DL10: ='Tabel Offset'!V11 -> 7.2625 | DM10: =DL10*DM$4 -> 7.2625 | DN10: =SUM(DI10,DK10,DM10) -> 42.8054 | DO10: =2*1/3*DN$2*DN10 -> 9.9879267 | DP10: =DO10+DD10 -> 70.070323 | DR10: ='Tabel Offset'!$A11 -> 2 | DS10: =IF(DR10="AP",0,IF(DR10="FP",'Tabel Offset'!$AA$4,DR10/20*'Tabel Offset'!$AA$4)) -> 9.507 | DT10: ='Tabel Offset'!V11 -> 7.2625 | DU10: =DT10*DU$4 -> 7.2625 | DV10: 7.3722 | DW10: =DV10*DW$4 -> 29.4888 | DX10: =(EA10-DT$2)/2+DT$2 -> 8.22295 | DY10: 6.352 | DZ10: =DY10*DZ$4 -> 6.352 | EA10: 8.5459 | EB10: =SUM(DU10,DW10,DZ10) -> 43.1033 | EC10: =2*1/3*((EA10-DT$2)/2)*EB10 -> 9.2801405 | ED10: =EC10+DP10 -> 79.350464
B11: ='Tabel Offset'!$A12 -> 3 | C11: =IF(B11="AP",0,IF(B11="FP",'Tabel Offset'!$AA$4,B11/20*'Tabel Offset'!$AA$4)) -> 14.2605 | D11: ='Tabel Offset'!B12 -> 0.241 | E11: =D11*E$4 -> 0.241 | F11: ='Tabel Offset'!C12 -> 2.3513 | G11: =F11*G$4 -> 9.4052 | H11: ='Tabel Offset'!D12 -> 3.0826 | I11: =H11*I$4 -> 3.0826 | J11: =SUM(E11,G11,I11) -> 12.7288 | K11: =2*1/3*J$2*J11 -> 2.1214667 | L11: =K11 -> 2.1214667 | N11: ='Tabel Offset'!$A12 -> 3 | O11: =IF(N11="AP",0,IF(N11="FP",'Tabel Offset'!$AA$4,N11/20*'Tabel Offset'!$AA$4)) -> 14.2605 | P11: ='Tabel Offset'!D11 -> 1.521 | Q11: =P11*Q$4 -> 1.521 | R11: ='Tabel Offset'!E12 -> 3.5334 | S11: =R11*S$4 -> 14.1336 | T11: ='Tabel Offset'!F12 -> 3.9111 | U11: =T11*U$4 -> 3.9111 | V11: =SUM(Q11,S11,U11) -> 19.5657 | W11: =2*1/3*V$2*V11 -> 3.26095 | X11: =W11+L11 -> 5.3824167 | Z11: ='Tabel Offset'!$A12 -> 3 | AA11: =IF(Z11="AP",0,IF(Z11="FP",'Tabel Offset'!$AA$4,Z11/20*'Tabel Offset'!$AA$4)) -> 14.2605 | AB11: ='Tabel Offset'!F12 -> 3.9111 | AC11: =AB11*AC$4 -> 3.9111 | AD11: ='Tabel Offset'!G12 -> 4.5731 | AE11: =AD11*AE$4 -> 18.2924 | AF11: ='Tabel Offset'!H12 -> 5.0314 | AG11: =AF11*AG$4 -> 5.0314 | AH11: =SUM(AC11,AE11,AG11) -> 27.2349 | AI11: =2*1/3*AH$2*AH11 -> 9.0783 | AJ11: =AI11+X11 -> 14.460717 | AL11: ='Tabel Offset'!$A12 -> 3 | AM11: =IF(AL11="AP",0,IF(AL11="FP",'Tabel Offset'!$AA$4,AL11/20*'Tabel Offset'!$AA$4)) -> 14.2605 | AN11: ='Tabel Offset'!H12 -> 5.0314 | AO11: =AN11*AO$4 -> 5.0314 | AP11: ='Tabel Offset'!I12 -> 5.4565 | AQ11: =AP11*AQ$4 -> 21.826 | AR11: ='Tabel Offset'!J11 -> 3.7939 | AS11: =AR11*AS$4 -> 3.7939 | AT11: =SUM(AO11,AQ11,AS11) -> 30.6513 | AU11: =2*1/3*AT$2*AT11 -> 10.2171 | AV11: =AU11+AJ11 -> 24.677817 | AX11: ='Tabel Offset'!$A12 -> 3 | AY11: =IF(AX11="AP",0,IF(AX11="FP",'Tabel Offset'!$AA$4,AX11/20*'Tabel Offset'!$AA$4)) -> 14.2605 | AZ11: ='Tabel Offset'!J12 -> 5.8073 | BA11: =AZ11*BA$4 -> 5.8073 | BB11: ='Tabel Offset'!K12 -> 6.1227 | BC11: =BB11*BC$4 -> 24.4908 | BD11: ='Tabel Offset'!L12 -> 6.4538 | BE11: =BD11*BE$4 -> 6.4538 | BF11: =SUM(BA11,BC11,BE11) -> 36.7519 | BG11: =2*1/3*BF$2*BF11 -> 12.250633 | BH11: =BG11+AV11 -> 36.92845 | BJ11: ='Tabel Offset'!$A12 -> 3 | BK11: =IF(BJ11="AP",0,IF(BJ11="FP",'Tabel Offset'!$AA$4,BJ11/20*'Tabel Offset'!$AA$4)) -> 14.2605 | BL11: ='Tabel Offset'!L12 -> 6.4538 | BM11: =BL11*BM$4 -> 6.4538 | BN11: ='Tabel Offset'!M12 -> 6.7876 | BO11: =BN11*BO$4 -> 27.1504 | BP11: ='Tabel Offset'!N12 -> 7.1274 | BQ11: =BP11*BQ$4 -> 7.1274 | BR11: =SUM(BM11,BO11,BQ11) -> 40.7316 | BS11: =2*1/3*BR$2*BR11 -> 13.5772 | BT11: =BS11+BH11 -> 50.50565 | BV11: ='Tabel Offset'!$A12 -> 3 | BW11: =IF(BV11="AP",0,IF(BV11="FP",'Tabel Offset'!$AA$4,BV11/20*'Tabel Offset'!$AA$4)) -> 14.2605 | BX11: ='Tabel Offset'!N12 -> 7.1274 | BY11: =BX11*BY$4 -> 7.1274 | BZ11: ='Tabel Offset'!O12 -> 7.3618 | CA11: =BZ11*CA$4 -> 29.4472 | CB11: ='Tabel Offset'!P12 -> 7.5007 | CC11: =CB11*CC$4 -> 7.5007 | CD11: =SUM(BY11,CA11,CC11) -> 44.0753 | CE11: =2*1/3*CD$2*CD11 -> 14.691767 | CF11: =CE11+BT11 -> 65.197417 | CH11: ='Tabel Offset'!$A12 -> 3 | CI11: =IF(CH11="AP",0,IF(CH11="FP",'Tabel Offset'!$AA$4,CH11/20*'Tabel Offset'!$AA$4)) -> 14.2605 | CJ11: ='Tabel Offset'!P12 -> 7.5007 | CK11: =CJ11*CK$4 -> 7.5007 | CL11: ='Tabel Offset'!Q12 -> 7.5528 | CM11: =CL11*CM$4 -> 30.2112 | CN11: ='Tabel Offset'!R12 -> 7.5999 | CO11: =CN11*CO$4 -> 7.5999 | CP11: =SUM(CK11,CM11,CO11) -> 45.3118 | CQ11: =2*1/3*CP$2*CP11 -> 7.5519667 | CR11: =CQ11+CF11 -> 72.749383 | CT11: ='Tabel Offset'!$A12 -> 3 | CU11: =IF(CT11="AP",0,IF(CT11="FP",'Tabel Offset'!$AA$4,CT11/20*'Tabel Offset'!$AA$4)) -> 14.2605 | CV11: ='Tabel Offset'!R12 -> 7.5999 | CW11: =CV11*CW$4 -> 7.5999 | CX11: ='Tabel Offset'!S12 -> 7.6603 | CY11: =CX11*CY$4 -> 30.6412 | CZ11: ='Tabel Offset'!T12 -> 7.7147 | DA11: =CZ11*DA$4 -> 7.7147 | DB11: =SUM(CW11,CY11,DA11) -> 45.9558 | DC11: =2*1/3*DB$2*DB11 -> 10.72302 | DD11: =DC11+CR11 -> 83.472403 | DF11: ='Tabel Offset'!$A12 -> 3 | DG11: =IF(DF11="AP",0,IF(DF11="FP",'Tabel Offset'!$AA$4,DF11/20*'Tabel Offset'!$AA$4)) -> 14.2605 | DH11: ='Tabel Offset'!T12 -> 7.7147 | DI11: =DH11*DI$4 -> 7.7147 | DJ11: ='Tabel Offset'!U12 -> 7.7634 | DK11: =DJ11*DK$4 -> 31.0536 | DL11: ='Tabel Offset'!V12 -> 7.8069 | DM11: =DL11*DM$4 -> 7.8069 | DN11: =SUM(DI11,DK11,DM11) -> 46.5752 | DO11: =2*1/3*DN$2*DN11 -> 10.867547 | DP11: =DO11+DD11 -> 94.33995 | DR11: ='Tabel Offset'!$A12 -> 3 | DS11: =IF(DR11="AP",0,IF(DR11="FP",'Tabel Offset'!$AA$4,DR11/20*'Tabel Offset'!$AA$4)) -> 14.2605 | DT11: ='Tabel Offset'!V12 -> 7.8069 | DU11: =DT11*DU$4 -> 7.8069 | DV11: 7.835 | DW11: =DV11*DW$4 -> 31.34 | DX11: =(EA11-DT$2)/2+DT$2 -> 8.1423 | DY11: 6.812 | DZ11: =DY11*DZ$4 -> 6.812 | EA11: 8.3846 | EB11: =SUM(DU11,DW11,DZ11) -> 45.9589 | EC11: =2*1/3*((EA11-DT$2)/2)*EB11 -> 7.4238943 | ED11: =EC11+DP11 -> 101.76384
B12: ='Tabel Offset'!$A13 -> 4 | C12: =IF(B12="AP",0,IF(B12="FP",'Tabel Offset'!$AA$4,B12/20*'Tabel Offset'!$AA$4)) -> 19.014 | D12: ='Tabel Offset'!B13 -> 0.53 | E12: =D12*E$4 -> 0.53 | F12: ='Tabel Offset'!C13 -> 4.538 | G12: =F12*G$4 -> 18.152 | H12: ='Tabel Offset'!D13 -> 5.2295 | I12: =H12*I$4 -> 5.2295 | J12: =SUM(E12,G12,I12) -> 23.9115 | K12: =2*1/3*J$2*J12 -> 3.98525 | L12: =K12 -> 3.98525 | N12: ='Tabel Offset'!$A13 -> 4 | O12: =IF(N12="AP",0,IF(N12="FP",'Tabel Offset'!$AA$4,N12/20*'Tabel Offset'!$AA$4)) -> 19.014 | P12: ='Tabel Offset'!D13 -> 5.2295 | Q12: =P12*Q$4 -> 5.2295 | R12: ='Tabel Offset'!E13 -> 5.6176 | S12: =R12*S$4 -> 22.4704 | T12: ='Tabel Offset'!F13 -> 5.942 | U12: =T12*U$4 -> 5.942 | V12: =SUM(Q12,S12,U12) -> 33.6419 | W12: =2*1/3*V$2*V12 -> 5.6069833 | X12: =W12+L12 -> 9.5922333 | Z12: ='Tabel Offset'!$A13 -> 4 | AA12: =IF(Z12="AP",0,IF(Z12="FP",'Tabel Offset'!$AA$4,Z12/20*'Tabel Offset'!$AA$4)) -> 19.014 | AB12: ='Tabel Offset'!F13 -> 5.942 | AC12: =AB12*AC$4 -> 5.942 | AD12: ='Tabel Offset'!G13 -> 6.4107 | AE12: =AD12*AE$4 -> 25.6428 | AF12: ='Tabel Offset'!H13 -> 6.8182 | AG12: =AF12*AG$4 -> 6.8182 | AH12: =SUM(AC12,AE12,AG12) -> 38.403 | AI12: =2*1/3*AH$2*AH12 -> 12.801 | AJ12: =AI12+X12 -> 22.393233 | AL12: ='Tabel Offset'!$A13 -> 4 | AM12: =IF(AL12="AP",0,IF(AL12="FP",'Tabel Offset'!$AA$4,AL12/20*'Tabel Offset'!$AA$4)) -> 19.014 | AN12: ='Tabel Offset'!H13 -> 6.8182 | AO12: =AN12*AO$4 -> 6.8182 | AP12: ='Tabel Offset'!I13 -> 7.1653 | AQ12: =AP12*AQ$4 -> 28.6612 | AR12: ='Tabel Offset'!J12 -> 5.8073 | AS12: =AR12*AS$4 -> 5.8073 | AT12: =SUM(AO12,AQ12,AS12) -> 41.2867 | AU12: =2*1/3*AT$2*AT12 -> 13.762233 | AV12: =AU12+AJ12 -> 36.155467 | AX12: ='Tabel Offset'!$A13 -> 4 | AY12: =IF(AX12="AP",0,IF(AX12="FP",'Tabel Offset'!$AA$4,AX12/20*'Tabel Offset'!$AA$4)) -> 19.014 | AZ12: ='Tabel Offset'!J13 -> 7.4387 | BA12: =AZ12*BA$4 -> 7.4387 | BB12: ='Tabel Offset'!K13 -> 7.645 | BC12: =BB12*BC$4 -> 30.58 | BD12: ='Tabel Offset'!L13 -> 7.7888 | BE12: =BD12*BE$4 -> 7.7888 | BF12: =SUM(BA12,BC12,BE12) -> 45.8075 | BG12: =2*1/3*BF$2*BF12 -> 15.269167 | BH12: =BG12+AV12 -> 51.424633 | BJ12: ='Tabel Offset'!$A13 -> 4 | BK12: =IF(BJ12="AP",0,IF(BJ12="FP",'Tabel Offset'!$AA$4,BJ12/20*'Tabel Offset'!$AA$4)) -> 19.014 | BL12: ='Tabel Offset'!L13 -> 7.7888 | BM12: =BL12*BM$4 -> 7.7888 | BN12: ='Tabel Offset'!M13 -> 7.8757 | BO12: =BN12*BO$4 -> 31.5028 | BP12: ='Tabel Offset'!N13 -> 7.9269 | BQ12: =BP12*BQ$4 -> 7.9269 | BR12: =SUM(BM12,BO12,BQ12) -> 47.2185 | BS12: =2*1/3*BR$2*BR12 -> 15.7395 | BT12: =BS12+BH12 -> 67.164133 | BV12: ='Tabel Offset'!$A13 -> 4 | BW12: =IF(BV12="AP",0,IF(BV12="FP",'Tabel Offset'!$AA$4,BV12/20*'Tabel Offset'!$AA$4)) -> 19.014 | BX12: ='Tabel Offset'!N13 -> 7.9269 | BY12: =BX12*BY$4 -> 7.9269 | BZ12: ='Tabel Offset'!O13 -> 7.9618 | CA12: =BZ12*CA$4 -> 31.8472 | CB12: ='Tabel Offset'!P13 -> 7.9876 | CC12: =CB12*CC$4 -> 7.9876 | CD12: =SUM(BY12,CA12,CC12) -> 47.7617 | CE12: =2*1/3*CD$2*CD12 -> 15.920567 | CF12: =CE12+BT12 -> 83.0847 | CH12: ='Tabel Offset'!$A13 -> 4 | CI12: =IF(CH12="AP",0,IF(CH12="FP",'Tabel Offset'!$AA$4,CH12/20*'Tabel Offset'!$AA$4)) -> 19.014 | CJ12: ='Tabel Offset'!P13 -> 7.9876 | CK12: =CJ12*CK$4 -> 7.9876 | CL12: ='Tabel Offset'!Q13 -> 7.9984 | CM12: =CL12*CM$4 -> 31.9936 | CN12: ='Tabel Offset'!R13 -> 8.0084 | CO12: =CN12*CO$4 -> 8.0084 | CP12: =SUM(CK12,CM12,CO12) -> 47.9896 | CQ12: =2*1/3*CP$2*CP12 -> 7.9982667 | CR12: =CQ12+CF12 -> 91.082967 | CT12: ='Tabel Offset'!$A13 -> 4 | CU12: =IF(CT12="AP",0,IF(CT12="FP",'Tabel Offset'!$AA$4,CT12/20*'Tabel Offset'!$AA$4)) -> 19.014 | CV12: ='Tabel Offset'!R13 -> 8.0084 | CW12: =CV12*CW$4 -> 8.0084 | CX12: ='Tabel Offset'!S13 -> 8.0215 | CY12: =CX12*CY$4 -> 32.086 | CZ12: ='Tabel Offset'!T13 -> 8.0335 | DA12: =CZ12*DA$4 -> 8.0335 | DB12: =SUM(CW12,CY12,DA12) -> 48.1279 | DC12: =2*1/3*DB$2*DB12 -> 11.229843 | DD12: =DC12+CR12 -> 102.31281 | DF12: ='Tabel Offset'!$A13 -> 4 | DG12: =IF(DF12="AP",0,IF(DF12="FP",'Tabel Offset'!$AA$4,DF12/20*'Tabel Offset'!$AA$4)) -> 19.014 | DH12: ='Tabel Offset'!T13 -> 8.0335 | DI12: =DH12*DI$4 -> 8.0335 | DJ12: ='Tabel Offset'!U13 -> 8.0445 | DK12: =DJ12*DK$4 -> 32.178 | DL12: ='Tabel Offset'!V13 -> 8.0545 | DM12: =DL12*DM$4 -> 8.0545 | DN12: =SUM(DI12,DK12,DM12) -> 48.266 | DO12: =2*1/3*DN$2*DN12 -> 11.262067 | DP12: =DO12+DD12 -> 113.57488 | DR12: ='Tabel Offset'!$A13 -> 4 | DS12: =IF(DR12="AP",0,IF(DR12="FP",'Tabel Offset'!$AA$4,DR12/20*'Tabel Offset'!$AA$4)) -> 19.014 | DT12: ='Tabel Offset'!V13 -> 8.0545 | DU12: =DT12*DU$4 -> 8.0545 | DV12: 8.0588 | DW12: =DV12*DW$4 -> 32.2352 | DX12: =(EA12-DT$2)/2+DT$2 -> 8.08885 | DY12: 7.017 | DZ12: =DY12*DZ$4 -> 7.017 | EA12: 8.2777 | EB12: =SUM(DU12,DW12,DZ12) -> 47.3067 | EC12: =2*1/3*((EA12-DT$2)/2)*EB12 -> 5.9559135 | ED12: =EC12+DP12 -> 119.53079
B13: ='Tabel Offset'!$A14 -> 5 | C13: =IF(B13="AP",0,IF(B13="FP",'Tabel Offset'!$AA$4,B13/20*'Tabel Offset'!$AA$4)) -> 23.7675 | D13: ='Tabel Offset'!B14 -> 1.075 | E13: =D13*E$4 -> 1.075 | F13: ='Tabel Offset'!C14 -> 6.5491 | G13: =F13*G$4 -> 26.1964 | H13: ='Tabel Offset'!D14 -> 6.9298 | I13: =H13*I$4 -> 6.9298 | J13: =SUM(E13,G13,I13) -> 34.2012 | K13: =2*1/3*J$2*J13 -> 5.7002 | L13: =K13 -> 5.7002 | N13: ='Tabel Offset'!$A14 -> 5 | O13: =IF(N13="AP",0,IF(N13="FP",'Tabel Offset'!$AA$4,N13/20*'Tabel Offset'!$AA$4)) -> 23.7675 | P13: ='Tabel Offset'!D13 -> 5.2295 | Q13: =P13*Q$4 -> 5.2295 | R13: ='Tabel Offset'!E14 -> 7.2003 | S13: =R13*S$4 -> 28.8012 | T13: ='Tabel Offset'!F14 -> 7.4073 | U13: =T13*U$4 -> 7.4073 | V13: =SUM(Q13,S13,U13) -> 41.438 | W13: =2*1/3*V$2*V13 -> 6.9063333 | X13: =W13+L13 -> 12.606533 | Z13: ='Tabel Offset'!$A14 -> 5 | AA13: =IF(Z13="AP",0,IF(Z13="FP",'Tabel Offset'!$AA$4,Z13/20*'Tabel Offset'!$AA$4)) -> 23.7675 | AB13: ='Tabel Offset'!F14 -> 7.4073 | AC13: =AB13*AC$4 -> 7.4073 | AD13: ='Tabel Offset'!G14 -> 7.6882 | AE13: =AD13*AE$4 -> 30.7528 | AF13: ='Tabel Offset'!H14 -> 7.9081 | AG13: =AF13*AG$4 -> 7.9081 | AH13: =SUM(AC13,AE13,AG13) -> 46.0682 | AI13: =2*1/3*AH$2*AH13 -> 15.356067 | AJ13: =AI13+X13 -> 27.9626 | AL13: ='Tabel Offset'!$A14 -> 5 | AM13: =IF(AL13="AP",0,IF(AL13="FP",'Tabel Offset'!$AA$4,AL13/20*'Tabel Offset'!$AA$4)) -> 23.7675 | AN13: ='Tabel Offset'!H14 -> 7.9081 | AO13: =AN13*AO$4 -> 7.9081 | AP13: ='Tabel Offset'!I14 -> 8.0208 | AQ13: =AP13*AQ$4 -> 32.0832 | AR13: ='Tabel Offset'!J13 -> 7.4387 | AS13: =AR13*AS$4 -> 7.4387 | AT13: =SUM(AO13,AQ13,AS13) -> 47.43 | AU13: =2*1/3*AT$2*AT13 -> 15.81 | AV13: =AU13+AJ13 -> 43.7726 | AX13: ='Tabel Offset'!$A14 -> 5 | AY13: =IF(AX13="AP",0,IF(AX13="FP",'Tabel Offset'!$AA$4,AX13/20*'Tabel Offset'!$AA$4)) -> 23.7675 | AZ13: ='Tabel Offset'!J14 -> 8.0664 | BA13: =AZ13*BA$4 -> 8.0664 | BB13: ='Tabel Offset'!K14 -> 8.0914 | BC13: =BB13*BC$4 -> 32.3656 | BD13: ='Tabel Offset'!L14 -> 8.1066 | BE13: =BD13*BE$4 -> 8.1066 | BF13: =SUM(BA13,BC13,BE13) -> 48.5386 | BG13: =2*1/3*BF$2*BF13 -> 16.179533 | BH13: =BG13+AV13 -> 59.952133 | BJ13: ='Tabel Offset'!$A14 -> 5 | BK13: =IF(BJ13="AP",0,IF(BJ13="FP",'Tabel Offset'!$AA$4,BJ13/20*'Tabel Offset'!$AA$4)) -> 23.7675 | BL13: ='Tabel Offset'!L14 -> 8.1066 | BM13: =BL13*BM$4 -> 8.1066 | BN13: ='Tabel Offset'!M14 -> 8.1149 | BO13: =BN13*BO$4 -> 32.4596 | BP13: ='Tabel Offset'!N14 -> 8.1196 | BQ13: =BP13*BQ$4 -> 8.1196 | BR13: =SUM(BM13,BO13,BQ13) -> 48.6858 | BS13: =2*1/3*BR$2*BR13 -> 16.2286 | BT13: =BS13+BH13 -> 76.180733 | BV13: ='Tabel Offset'!$A14 -> 5 | BW13: =IF(BV13="AP",0,IF(BV13="FP",'Tabel Offset'!$AA$4,BV13/20*'Tabel Offset'!$AA$4)) -> 23.7675 | BX13: ='Tabel Offset'!N14 -> 8.1196 | BY13: =BX13*BY$4 -> 8.1196 | BZ13: ='Tabel Offset'!O14 -> 8.1232 | CA13: =BZ13*CA$4 -> 32.4928 | CB13: ='Tabel Offset'!P14 -> 8.1263 | CC13: =CB13*CC$4 -> 8.1263 | CD13: =SUM(BY13,CA13,CC13) -> 48.7387 | CE13: =2*1/3*CD$2*CD13 -> 16.246233 | CF13: =CE13+BT13 -> 92.426967 | CH13: ='Tabel Offset'!$A14 -> 5 | CI13: =IF(CH13="AP",0,IF(CH13="FP",'Tabel Offset'!$AA$4,CH13/20*'Tabel Offset'!$AA$4)) -> 23.7675 | CJ13: ='Tabel Offset'!P14 -> 8.1263 | CK13: =CJ13*CK$4 -> 8.1263 | CL13: ='Tabel Offset'!Q14 -> 8.1276 | CM13: =CL13*CM$4 -> 32.5104 | CN13: ='Tabel Offset'!R14 -> 8.1289 | CO13: =CN13*CO$4 -> 8.1289 | CP13: =SUM(CK13,CM13,CO13) -> 48.7656 | CQ13: =2*1/3*CP$2*CP13 -> 8.1276 | CR13: =CQ13+CF13 -> 100.55457 | CT13: ='Tabel Offset'!$A14 -> 5 | CU13: =IF(CT13="AP",0,IF(CT13="FP",'Tabel Offset'!$AA$4,CT13/20*'Tabel Offset'!$AA$4)) -> 23.7675 | CV13: ='Tabel Offset'!R14 -> 8.1289 | CW13: =CV13*CW$4 -> 8.1289 | CX13: ='Tabel Offset'!S14 -> 8.1305 | CY13: =CX13*CY$4 -> 32.522 | CZ13: ='Tabel Offset'!T14 -> 8.1319 | DA13: =CZ13*DA$4 -> 8.1319 | DB13: =SUM(CW13,CY13,DA13) -> 48.7828 | DC13: =2*1/3*DB$2*DB13 -> 11.382653 | DD13: =DC13+CR13 -> 111.93722 | DF13: ='Tabel Offset'!$A14 -> 5 | DG13: =IF(DF13="AP",0,IF(DF13="FP",'Tabel Offset'!$AA$4,DF13/20*'Tabel Offset'!$AA$4)) -> 23.7675 | DH13: ='Tabel Offset'!T14 -> 8.1319 | DI13: =DH13*DI$4 -> 8.1319 | DJ13: ='Tabel Offset'!U14 -> 8.1332 | DK13: =DJ13*DK$4 -> 32.5328 | DL13: ='Tabel Offset'!V14 -> 8.1343 | DM13: =DL13*DM$4 -> 8.1343 | DN13: =SUM(DI13,DK13,DM13) -> 48.799 | DO13: =2*1/3*DN$2*DN13 -> 11.386433 | DP13: =DO13+DD13 -> 123.32365 | DR13: ='Tabel Offset'!$A14 -> 5 | DS13: =IF(DR13="AP",0,IF(DR13="FP",'Tabel Offset'!$AA$4,DR13/20*'Tabel Offset'!$AA$4)) -> 23.7675 | DT13: ='Tabel Offset'!V14 -> 8.1343 | DU13: =DT13*DU$4 -> 8.1343 | DV13: 8.1346 | DW13: =DV13*DW$4 -> 32.5384 | DX13: =(EA13-DT$2)/2+DT$2 -> 8.0368 | DY13: 7.07 | DZ13: =DY13*DZ$4 -> 7.07 | EA13: 8.1736 | EB13: =SUM(DU13,DW13,DZ13) -> 47.7427 | EC13: =2*1/3*((EA13-DT$2)/2)*EB13 -> 4.3541342 | ED13: =EC13+DP13 -> 127.67779
B14: ='Tabel Offset'!$A15 -> 6 | C14: =IF(B14="AP",0,IF(B14="FP",'Tabel Offset'!$AA$4,B14/20*'Tabel Offset'!$AA$4)) -> 28.521 | D14: ='Tabel Offset'!B15 -> 2.979 | E14: =D14*E$4 -> 2.979 | F14: ='Tabel Offset'!C15 -> 7.4683 | G14: =F14*G$4 -> 29.8732 | H14: ='Tabel Offset'!D15 -> 7.765 | I14: =H14*I$4 -> 7.765 | J14: =SUM(E14,G14,I14) -> 40.6172 | K14: =2*1/3*J$2*J14 -> 6.7695333 | L14: =K14 -> 6.7695333 | N14: ='Tabel Offset'!$A15 -> 6 | O14: =IF(N14="AP",0,IF(N14="FP",'Tabel Offset'!$AA$4,N14/20*'Tabel Offset'!$AA$4)) -> 28.521 | P14: ='Tabel Offset'!D15 -> 7.765 | Q14: =P14*Q$4 -> 7.765 | R14: ='Tabel Offset'!E15 -> 7.9116 | S14: =R14*S$4 -> 31.6464 | T14: ='Tabel Offset'!F15 -> 8.0008 | U14: =T14*U$4 -> 8.0008 | V14: =SUM(Q14,S14,U14) -> 47.4122 | W14: =2*1/3*V$2*V14 -> 7.9020333 | X14: =W14+L14 -> 14.671567 | Z14: ='Tabel Offset'!$A15 -> 6 | AA14: =IF(Z14="AP",0,IF(Z14="FP",'Tabel Offset'!$AA$4,Z14/20*'Tabel Offset'!$AA$4)) -> 28.521 | AB14: ='Tabel Offset'!F15 -> 8.0008 | AC14: =AB14*AC$4 -> 8.0008 | AD14: ='Tabel Offset'!G15 -> 8.0995 | AE14: =AD14*AE$4 -> 32.398 | AF14: ='Tabel Offset'!H15 -> 8.1225 | AG14: =AF14*AG$4 -> 8.1225 | AH14: =SUM(AC14,AE14,AG14) -> 48.5213 | AI14: =2*1/3*AH$2*AH14 -> 16.173767 | AJ14: =AI14+X14 -> 30.845333 | AL14: ='Tabel Offset'!$A15 -> 6 | AM14: =IF(AL14="AP",0,IF(AL14="FP",'Tabel Offset'!$AA$4,AL14/20*'Tabel Offset'!$AA$4)) -> 28.521 | AN14: ='Tabel Offset'!H15 -> 8.1225 | AO14: =AN14*AO$4 -> 8.1225 | AP14: ='Tabel Offset'!I15 -> 8.1308 | AQ14: =AP14*AQ$4 -> 32.5232 | AR14: ='Tabel Offset'!J14 -> 8.0664 | AS14: =AR14*AS$4 -> 8.0664 | AT14: =SUM(AO14,AQ14,AS14) -> 48.7121 | AU14: =2*1/3*AT$2*AT14 -> 16.237367 | AV14: =AU14+AJ14 -> 47.0827 | AX14: ='Tabel Offset'!$A15 -> 6 | AY14: =IF(AX14="AP",0,IF(AX14="FP",'Tabel Offset'!$AA$4,AX14/20*'Tabel Offset'!$AA$4)) -> 28.521 | AZ14: ='Tabel Offset'!J15 -> 8.1437 | BA14: =AZ14*BA$4 -> 8.1437 | BB14: ='Tabel Offset'!K15 -> 8.1406 | BC14: =BB14*BC$4 -> 32.5624 | BD14: ='Tabel Offset'!L15 -> 8.1419 | BE14: =BD14*BE$4 -> 8.1419 | BF14: =SUM(BA14,BC14,BE14) -> 48.848 | BG14: =2*1/3*BF$2*BF14 -> 16.282667 | BH14: =BG14+AV14 -> 63.365367 | BJ14: ='Tabel Offset'!$A15 -> 6 | BK14: =IF(BJ14="AP",0,IF(BJ14="FP",'Tabel Offset'!$AA$4,BJ14/20*'Tabel Offset'!$AA$4)) -> 28.521 | BL14: ='Tabel Offset'!L15 -> 8.1419 | BM14: =BL14*BM$4 -> 8.1419 | BN14: ='Tabel Offset'!M15 -> 8.1426 | BO14: =BN14*BO$4 -> 32.5704 | BP14: ='Tabel Offset'!N15 -> 8.1431 | BQ14: =BP14*BQ$4 -> 8.1431 | BR14: =SUM(BM14,BO14,BQ14) -> 48.8554 | BS14: =2*1/3*BR$2*BR14 -> 16.285133 | BT14: =BS14+BH14 -> 79.6505 | BV14: ='Tabel Offset'!$A15 -> 6 | BW14: =IF(BV14="AP",0,IF(BV14="FP",'Tabel Offset'!$AA$4,BV14/20*'Tabel Offset'!$AA$4)) -> 28.521 | BX14: ='Tabel Offset'!N15 -> 8.1431 | BY14: =BX14*BY$4 -> 8.1431 | BZ14: ='Tabel Offset'!O15 -> 8.1434 | CA14: =BZ14*CA$4 -> 32.5736 | CB14: ='Tabel Offset'!P15 -> 8.1438 | CC14: =CB14*CC$4 -> 8.1438 | CD14: =SUM(BY14,CA14,CC14) -> 48.8605 | CE14: =2*1/3*CD$2*CD14 -> 16.286833 | CF14: =CE14+BT14 -> 95.937333 | CH14: ='Tabel Offset'!$A15 -> 6 | CI14: =IF(CH14="AP",0,IF(CH14="FP",'Tabel Offset'!$AA$4,CH14/20*'Tabel Offset'!$AA$4)) -> 28.521 | CJ14: ='Tabel Offset'!P15 -> 8.1438 | CK14: =CJ14*CK$4 -> 8.1438 | CL14: ='Tabel Offset'!Q15 -> 8.144 | CM14: =CL14*CM$4 -> 32.576 | CN14: ='Tabel Offset'!R15 -> 8.144 | CO14: =CN14*CO$4 -> 8.144 | CP14: =SUM(CK14,CM14,CO14) -> 48.8638 | CQ14: =2*1/3*CP$2*CP14 -> 8.1439667 | CR14: =CQ14+CF14 -> 104.0813 | CT14: ='Tabel Offset'!$A15 -> 6 | CU14: =IF(CT14="AP",0,IF(CT14="FP",'Tabel Offset'!$AA$4,CT14/20*'Tabel Offset'!$AA$4)) -> 28.521 | CV14: ='Tabel Offset'!R15 -> 8.144 | CW14: =CV14*CW$4 -> 8.144 | CX14: ='Tabel Offset'!S15 -> 8.144 | CY14: =CX14*CY$4 -> 32.576 | CZ14: ='Tabel Offset'!T15 -> 8.144 | DA14: =CZ14*DA$4 -> 8.144 | DB14: =SUM(CW14,CY14,DA14) -> 48.864 | DC14: =2*1/3*DB$2*DB14 -> 11.4016 | DD14: =DC14+CR14 -> 115.4829 | DF14: ='Tabel Offset'!$A15 -> 6 | DG14: =IF(DF14="AP",0,IF(DF14="FP",'Tabel Offset'!$AA$4,DF14/20*'Tabel Offset'!$AA$4)) -> 28.521 | DH14: ='Tabel Offset'!T15 -> 8.144 | DI14: =DH14*DI$4 -> 8.144 | DJ14: ='Tabel Offset'!U15 -> 8.144 | DK14: =DJ14*DK$4 -> 32.576 | DL14: ='Tabel Offset'!V15 -> 8.144 | DM14: =DL14*DM$4 -> 8.144 | DN14: =SUM(DI14,DK14,DM14) -> 48.864 | DO14: =2*1/3*DN$2*DN14 -> 11.4016 | DP14: =DO14+DD14 -> 126.8845 | DR14: ='Tabel Offset'!$A15 -> 6 | DS14: =IF(DR14="AP",0,IF(DR14="FP",'Tabel Offset'!$AA$4,DR14/20*'Tabel Offset'!$AA$4)) -> 28.521 | DT14: ='Tabel Offset'!V15 -> 8.144 | DU14: =DT14*DU$4 -> 8.144 | DV14: 8.144 | DW14: =DV14*DW$4 -> 32.576 | DX14: =(EA14-DT$2)/2+DT$2 -> 7.9854 | DY14: 7.118 | DZ14: =DY14*DZ$4 -> 7.118 | EA14: 8.0708 | EB14: =SUM(DU14,DW14,DZ14) -> 47.838 | EC14: =2*1/3*((EA14-DT$2)/2)*EB14 -> 2.7235768 | ED14: =EC14+DP14 -> 129.60808
